Workbook

Sheet 全運通
K3: 日期 | L3: =NOW() -> 46083.416
A4: 員工出勤動態日報表
A5: 單位 | J5: 人數統計 | K5: 單位加總 | L5: 實到人數 | M5: 出勤率
A6: 全運通 | B6: 土城廠 | C6: 主管 | J6: =COUNTA(D6:I6) -> 0 | K6: =J6+J7+J9 -> 2 | L6: 2 | M6: =L6/K6 -> 1
C7: 土城行政助理 | D7: 陳泱瑄 | J7: =COUNTA(D7:I7) -> 1 | S7: =COUNTA(D7:R7) -> 2
B8: 中和廠 | C8: 主管 | J8: =COUNTA(D8:I8) -> 0 | S8: =COUNTA(D8:R8) -> 1
C9: 中和行政助理 | D9: 陳蓉穎 | J9: =COUNTA(D9:I9) -> 1 | S9: =COUNTA(D9:R9) -> 2 | T9: =SUM(S7:S9) -> 5 | V9: 總員編 | W9: 3 | Y9: 3 | Z9: 0 | AA9: 0 | AB9: =SUM(Y9:AA9) -> 3 | AC9: =T9 -> 5 | AD9: =IF(AB9<AC9,AC9-AB9,0) -> 2 | AE9: =IF(AB9>AC9,AB9-AC9,0) -> 0

Sheet Sheet2
A1: 室/站/專案
D2: 編制人數 | E2: 現有人數 | F2: 缺額 | G2: 41275 | H2: 41358 | I2: 1-3離職人數 | J2: 離職率
A3: 總經理室 | D3: 10 | E3: 7 | F3: =D3-E3 -> 3 | G3: 10 | H3: =E3 -> 7 | I3: 0 | J3: =I3/((G3+H3)/2) -> 0
A4: 資源循環研發中心 | D4: 4 | E4: 4 | F4: =D4-E4 -> 0 | G4: 4 | H4: =E4 -> 4 | I4: 0 | J4: =I4/((G4+H4)/2) -> 0
A5: 稽核室 | D5: 3 | E5: 4 | F5: =D5-E5 -> -1 | G5: 3 | H5: =E5 -> 4 | I5: 0 | J5: =I5/((G5+H5)/2) -> 0
A6: 副總 | D6: 1 | E6: 1 | F6: =D6-E6 -> 0 | G6: 1 | H6: =E6 -> 1 | I6: 0 | J6: =I6/((G6+H6)/2) -> 0
A7: 財務組 | E7: 3 | F7: =D7-E7 -> -3 | G7: 3 | H7: =E7 -> 3 | I7: 0 | J7: =I7/((G7+H7)/2) -> 0
A8: 會計組 | E8: 9 | F8: =D8-E8 -> -9 | G8: 9 | H8: =E8 -> 9 | I8: 1 | J8: =I8/((G8+H8)/2) -> 0.11111111
A9: 投資組 | E9: 3 | F9: =D9-E9 -> -3 | G9: 3 | H9: =E9 -> 3 | I9: 0 | J9: =I9/((G9+H9)/2) -> 0
A10: 策略管理處與行政暨物料管理組 | E10: 3 | F10: =D10-E10 -> -3 | G10: 3 | H10: =E10 -> 3 | I10: 0 | J10: =I10/((G10+H10)/2) -> 0
A11: 公關行銷組 | E11: 2 | F11: =D11-E11 -> -2 | G11: 2 | H11: =E11 -> 2 | I11: 0 | J11: =I11/((G11+H11)/2) -> 0
A12: 人資策略組 | E12: 5 | F12: =D12-E12 -> -5 | G12: 6 | H12: =E12 -> 5 | I12: 2 | J12: =I12/((G12+H12)/2) -> 0.36363636
A13: 法務環安組 | E13: 2 | F13: =D13-E13 -> -2 | G13: 2 | H13: =E13 -> 2 | I13: 0 | J13: =I13/((G13+H13)/2) -> 0
A14: 資訊策略組 | E14: 5 | F14: =D14-E14 -> -5 | G14: 5 | H14: =E14 -> 5 | I14: 0 | J14: =I14/((G14+H14)/2) -> 0
A15: 處主管 | E15: 1 | F15: =D15-E15 -> -1 | G15: 1 | H15: =E15 -> 1 | I15: 0 | J15: =I15/((G15+H15)/2) -> 0
A16: 行政室 | E16: 6 | F16: =D16-E16 -> -6 | G16: 6 | H16: =E16 -> 6 | I16: 0 | J16: =I16/((G16+H16)/2) -> 0
A17: 中區市場開發部 | E17: 3 | F17: =D17-E17 -> -3 | G17: 3 | H17: =E17 -> 3 | I17: 0 | J17: =I17/((G17+H17)/2) -> 0
A18: 中區-倉儲物流管理部 | B18: 主任 | E18: 1 | F18: =D18-E18 -> -1 | G18: 1 | H18: =E18 -> 1 | I18: 0 | J18: =I18/((G18+H18)/2) -> 0
B19: 副主任 | F19: =D19-E19 -> 0 | H19: =E19 -> 0 | I19: 0 | J19: 0
B20: 中部專案 | E20: 0 | F20: =D20-E20 -> 0 | H20: =E20 -> 0 | I20: 0 | J20: 0
C21: 中部倉儲管理 | E21: 11 | F21: =D21-E21 -> -11 | G21: 11 | H21: =E21 -> 11 | I21: 1 | J21: =I21/((G21+H21)/2) -> 0.090909091
C22: 中部資收 | E22: 6 | F22: =D22-E22 -> -6 | G22: 7 | H22: =E22 -> 6 | I22: 2 | J22: =I22/((G22+H22)/2) -> 0.30769231
B23: 文山專案 | C23: 文山專案 | E23: 22 | F23: =D23-E23 -> -22 | G23: 18 | H23: =E23 -> 22 | I23: 7 | J23: =I23/((G23+H23)/2) -> 0.35
C24: 人力仲介 | E24: 0 | F24: =D24-E24 -> 0 | G24: 0 | H24: =E24 -> 0 | I24: 0 | J24: 0
B25: 輔祥專案 | C25: 輔祥 | E25: 2 | F25: =D25-E25 -> -2 | G25: 2 | H25: =E25 -> 2 | I25: 0 | J25: =I25/((G25+H25)/2) -> 0
B26: 友達專案 | C26: 副主任 | E26: 2 | F26: =D26-E26 -> -2 | G26: 1 | H26: =E26 -> 2 | I26: 0 | J26: =I26/((G26+H26)/2) -> 0
C27: 友達-資收區(一、二期) | E27: 9 | F27: =D27-E27 -> -9 | G27: 9 | H27: =E27 -> 9 | I27: 0 | J27: =I27/((G27+H27)/2) -> 0
C28: 友達-資收區(三期) | E28: 8 | F28: =D28-E28 -> -8 | G28: 8 | H28: =E28 -> 8 | I28: 0 | J28: =I28/((G28+H28)/2) -> 0
C29: 友達-包材區 | E29: 12 | F29: =D29-E29 -> -12 | G29: 11 | H29: =E29 -> 12 | I29: 0 | J29: =I29/((G29+H29)/2) -> 0
C30: 友達-后里包材清潔區 | E30: 30 | F30: =D30-E30 -> -30 | G30: 32 | H30: =E30 -> 30 | I30: 2 | J30: =I30/((G30+H30)/2) -> 0.064516129
C31: 友達-后里包材清潔區(人力仲介) | E31: 5 | F31: =D31-E31 -> -5 | G31: 5 | H31: =E31 -> 5 | I31: 0 | J31: =I31/((G31+H31)/2) -> 0
C32: 友達-資收區(七星) | E32: 6 | F32: =D32-E32 -> -6 | G32: 6 | H32: =E32 -> 6 | I32: 0 | J32: =I32/((G32+H32)/2) -> 0
A33: 北區市場開發部 | E33: 2 | F33: =D33-E33 -> -2 | G33: 1 | H33: =E33 -> 2 | I33: 0 | J33: =I33/((G33+H33)/2) -> 0
A34: 北區-倉儲物流管理部 | B34: 北部資收 | C34: 蘆竹 | E34: 7 | F34: =D34-E34 -> -7 | G34: 10 | H34: =E34 -> 7 | I34: 4 | J34: =I34/((G34+H34)/2) -> 0.47058824
C35: 龍潭 | E35: 1 | F35: =D35-E35 -> -1 | G35: 4 | H35: =E35 -> 1 | I35: 3 | J35: =I35/((G35+H35)/2) -> 1.2
C36: 人力仲介 | E36: 0 | F36: =D36-E36 -> 0 | G36: 0 | H36: =E36 -> 0 | I36: 0 | J36: =I36/((G36+H36)/2) -> #DIV/0!
C37: 桃園 | E37: 1 | F37: =D37-E37 -> -1 | G37: 1 | H37: =E37 -> 1 | I37: 1 | J37: =I37/((G37+H37)/2) -> 1
A38: 南區市場開發部 | E38: 4 | F38: =D38-E38 -> -4 | G38: 3 | H38: =E38 -> 4 | I38: 1 | J38: =I38/((G38+H38)/2) -> 0.28571429
A39: 南區-倉儲物流管理部 | B39: 南部專案 | C39: 南科3m | E39: 33 | F39: =D39-E39 -> -33 | G39: 28 | H39: =E39 -> 33 | I39: 2 | J39: =I39/((G39+H39)/2) -> 0.06557377
C40: 中強 | E40: 1 | F40: =D40-E40 -> -1 | G40: 1 | H40: =E40 -> 1 | I40: 0 | J40: =I40/((G40+H40)/2) -> 0
...

Sheet 各站員工名單
A1: 各站單位人員 | D1: 各站單位人員 | J1: 主 管 | K1: 成員 | X1: 人數統計 | Y1: 單位加總
A2: 董事會 | D2: 董事會 | I2: 董事長 | J2: 林盟洲 | X2: =COUNTA(J2:W2) -> 1
I3: 副董事長 | J3: 洪勝裕 | X3: =COUNTA(J3:W3) -> 1 | Y3: =SUM(X2:X3) -> 2
A4: 總經理 | D4: 總經理室 | F4: 總經理室 | I4: 總經理 | J4: 林盟洲 | X4: =COUNTA(J4:W4) -> 1
I5: 顧問 | K5: 顏嘉賢 | X5: =COUNTA(K5:W5) -> 1
I6: 資深高級管理師 | K6: 林茹雯 | X6: =COUNTA(K6:W6) -> 1
I7: 管理師 | X7: =COUNTA(J7:W7) -> 0
I8: 實習生 | X8: =COUNTA(K8:W8) -> 0
I9: 儲備幹部(幹訓班) | X9: =COUNTA(J9:W9) -> 0 | Y9: =SUM(X4:X9) -> 3 | AA9: 總員編 | AB9: 4 | AE9: (原編3，增加顧問1名)
A10: 稽核室 | D10: 資源循環研發處 | F10: 主管 | I10: 經理 | J10: 李韶華 | X10: =COUNTA(J10:W10) -> 1 | Y10: 1 | Z10: 1
F11: 資源循環研發處 | I11: 主管(李韶華兼任) | X11: =COUNTA(J11:W11) -> 0
I12: 副管理師 | K12: 張福麟 | X12: =COUNTA(J12:W12) -> 1
I13: 實習生 | X13: =COUNTA(J13:W13) -> 0 | Y13: =SUM(X11:X13) -> 1 | Z13: 2
F14: 知識創新部 | I14: 襄理 | K14: 邱淑婷 | L14: 阮常新 | X14: =COUNTA(J14:W14) -> 2
I15: 資深高級管理師 | X15: =COUNTA(J15:W15) -> 0
I16: 高級管理師 | X16: =COUNTA(J16:W16) -> 0
I17: 事務員 | K17: 張雅涵 | X17: =COUNTA(J17:W17) -> 1 | Y17: =SUM(X14:X17) -> 3 | Z17: 3
F18: 研發部 | I18: 副理 | K18: 施承享 | X18: =COUNTA(J18:M18) -> 1
I19: 專員 | X19: =COUNTA(K19:W19) -> 0
I20: 高級管理師 | K20: 呂智偉 | X20: =COUNTA(K20:W20) -> 1
I21: 助理管理師 | K21: 曾炘宸 | X21: =COUNTA(K21:W21) -> 1 | Y21: =SUM(X18:X21) -> 3 | Z21: 3
F22: 環保顧問部 | I22: 高級管理師 | K22: 陳麗芳 | X22: =COUNTA(K22:W22) -> 1 | Y22: =SUM(X22:X23) -> 2
I23: 管理師 | K23: 陳信佳 | X23: =COUNTA(K23:W23) -> 1 | Y23: =Y22+Y21+Y17+Y13+Y10 -> 10 | Z23: 2 | AA23: 總員編 | AB23: 9
A24: 稽核室 | D24: 稽核室 | I24: 副理 | J24: 羅儷英 | X24: =COUNTA(J24:W24) -> 1
I25: 高級管理師 | X25: =COUNTA(J25:W25) -> 0
I26: 管理師 | X26: =COUNTA(J26:W26) -> 0
I27: 副管理師 | K27: 錢煥昇 | X27: =COUNTA(J27:W27) -> 1 | Y27: =SUM(X24:X27) -> 2 | AA27: 總員編 | AB27: 4
A28: 財務處 | C28: 副總經理 | D28: 財務部 | I28: 副理 | J28: 王雅祈 | X28: =COUNTA(J28:W28) -> 1 | Y28: =X28 -> 1 | Z28: 1
C29: 財務組 | F29: 財務課 | I29: 主任 | J29: 蔡佩君 | X29: =COUNTA(J29:W29) -> 1
I30: 主任 | X30: =COUNTA(J30:W30) -> 0
I31: 助理管理師 | X31: =COUNTA(J31:W31) -> 0
I32: 事務員 | K32: 吳宜蒨 | L32: 翁琳婷 | X32: =COUNTA(J32:W32) -> 2 | Y32: =SUM(X29:X32) -> 3 | Z32: 3
F33: 會計課 | I33: 主任 | J33: 莊宜陵 | X33: =COUNTA(J33:W33) -> 1
I34: 助理管理師 | K34: 吳佳純 | L34: 蕭秀玲 | M34: 黃意茗 | N34: 黃美萍 | O34: 劉靜文 | X34: =COUNTA(J34:W34) -> 5
I35: 事務員 | X35: =COUNTA(J35:W35) -> 0 | Y35: =SUM(X33:X35) -> 6 | Z35: 6
C36: 投資組 | F36: 投資課 | I36: 襄理 | X36: =COUNTA(J36:W36) -> 0
I37: 大陸投資 | K37: 巫志誠 | X37: =COUNTA(J37:W37) -> 1
I38: 專案經理 | X38: 0
I39: 助理管理師 | K39: 劉晏汝 | X39: =COUNTA(J39:W39) -> 1 | Y39: =SUM(X36:X39) -> 2 | Z39: 3
F40: 法務課 | I40: 高級管理師 | K40: 賴柏州 | X40: =COUNTA(J40:W40) -> 1 | Y40: =X40 -> 1 | Z40: 1
...

Sheet 員工出勤日報表
A1: =TODAY() -> 46083
A2: 處/別 | B2: 室/站/專案 | F2: 員編
G3: 應到人數 | H3: 實到人數 | I3: 出勤率
A4: =各站員工名單!A2 -> 董事會 | B4: =A4 -> 董事會 | G4: =各站員工名單!Y3 -> 2 | H4: 2 | I4: =H4/G4 -> 1
A5: 總經理室 | B5: =A5 -> 總經理室 | G5: =各站員工名單!Y9 -> 3 | H5: 3 | I5: =H5/G5 -> 1
A6: 資源循環研發處 | B6: =A6 -> 資源循環研發處 | G6: =各站員工名單!Y10+各站員工名單!Y13 -> 2 | H6: 2 | I6: =H6/G6 -> 1
B7: 知識創新部 | G7: =各站員工名單!Y17 -> 3 | H7: 2 | I7: =H7/G7 -> 0.66666667 | J7: 出差1名(阮常新1200-1730)
B8: 研發部 | G8: =各站員工名單!Y21 -> 3 | H8: 3 | I8: =H8/G8 -> 1
B9: 環保顧問部 | G9: =各站員工名單!Y22 -> 2 | H9: 2 | I9: =H9/G9 -> 1
A10: 稽核室 | B10: =A10 -> 稽核室 | G10: =各站員工名單!Y27 -> 2 | H10: 2 | I10: =H10/G10 -> 1
A11: =各站員工名單!D28 -> 財務部 | B11: 副理 | G11: =各站員工名單!Y28 -> 1 | H11: 1 | I11: =H11/G11 -> 1
B12: 財務課 | G12: =各站員工名單!Y32 -> 3 | H12: 3 | I12: =H12/G12 -> 1
B13: 會計課 | G13: =各站員工名單!Y35 -> 6 | H13: 5 | I13: =H13/G13 -> 0.83333333 | J13: 特休1名(莊宜陵)
B14: 投資課 | G14: =各站員工名單!Y39 -> 2 | H14: 2 | I14: =H14/G14 -> 1
B15: 法務課 | G15: =各站員工名單!Y40 -> 1 | H15: 1 | I15: =H15/G15 -> 1 | J15: 事假1名(賴柏州1300-1730)
A16: =各站員工名單!D42 -> 行銷部 | B16: 行銷部 | G16: =各站員工名單!Y45 -> 3 | H16: 3 | I16: =H16/G16 -> 1 | J16: 特休1名(許家惠1330-1730)
A17: =各站員工名單!D46 -> 人資部 | B17: 人資部 | G17: =各站員工名單!Y53 -> 8 | H17: 8 | I17: =H17/G17 -> 1 | J17: 休假1名(卓怡伶1300-1730)
A18: =各站員工名單!D54 -> 資訊部 | B18: 資訊部 | G18: =各站員工名單!Y62 -> 9 | H18: 9 | I18: =H18/G18 -> 1
A19: 業務開發處 | B19: 處主管 | G19: =各站員工名單!Y63 -> 1 | H19: 1 | I19: =H19/G19 -> 1
B20: 業務處行政課 | G20: =各站員工名單!X64 -> 1 | H20: 1 | I20: =H20/G20 -> 1
B21: 電子商務部 | G21: =各站員工名單!Y66 -> 1 | H21: 1 | I21: =H21/G21 -> 1
B22: 北區業務部 | C22: 業務課 | G22: =各站員工名單!Y68 -> 0 | H22: 0 | I22: =H22/G22 -> #DIV/0!
C23: 物流作業課 | D23: 倉儲物流組 | G23: =各站員工名單!Y71 -> 1 | H23: 1 | I23: =H23/G23 -> 1
D24: 作業組 | E24: 業務-燿華電子 | G24: =各站員工名單!Y76 -> 7 | H24: 7 | I24: =H24/G24 -> 1
E25: 業務-京元電子 | G25: =各站員工名單!Y78 -> 2 | H25: 2 | I25: =H25/G25 -> 1
B26: 中區業務部 | C26: 業務課 | G26: =各站員工名單!Y85 -> 8 | H26: 8 | I26: 1
C27: 物流作業一課 | D27: 主管 | G27: =各站員工名單!Y86 -> 1 | H27: 1 | I27: =H27/G27 -> 1
D28: 倉儲物流組 | E28: 業務廢棄物專案 | G28: =各站員工名單!X85 -> 1 | H28: 1 | I28: =H28/G28 -> 1
E29: 物流管理組 | G29: =各站員工名單!Y96 -> 14 | H29: 14 | I29: =H29/G29 -> 1
D30: 作業組 | E30: 中部倉庫 | G30: =各站員工名單!Y99 -> 6 | H30: 6 | I30: =H30/G30 -> 1
C31: 物流作業二課 | D31: 主管 | G31: =各站員工名單!X100 -> 0 | H31: 0 | I31: =H31/G31 -> #DIV/0!
D32: 倉儲物流組 | G32: 0 | H32: 0 | I32: =H32/G32 -> #DIV/0!
D33: 作業組 | E33: 友達-七星 | G33: =各站員工名單!Y104 -> 7 | H33: 7 | I33: =H33/G33 -> 1
E34: 友達資收專案 | G34: =各站員工名單!Y112 -> 16 | H34: 16 | I34: =H34/G34 -> 1
E35: 友達包材 | G35: =各站員工名單!Y117 -> 9 | H35: 8 | I35: =H35/G35 -> 0.88888889 | J35: 病假1名(葉銘珠)
E36: 美光電子 | G36: =各站員工名單!Y119 -> 2 | H36: 2 | I36: =H36/G36 -> 1
C37: 物流作業三課 | D37: 主管 | G37: =各站員工名單!Y120 -> 1 | H37: 1 | I37: =H37/G37 -> 1
D38: 倉儲物流組 | G38: 0 | H38: 0 | I38: =H38/G38 -> #DIV/0!
D39: 作業組 | E39: 文山專案 | G39: =各站員工名單!Y130 -> 15 | H39: 15 | I39: =H39/G39 -> 1
B40: 南區業務部 | C40: 主管 | G40: =各站員工名單!Y131 -> 1 | H40: 1 | I40: =H40/G40 -> 1
...

Sheet 業務開發處
C1: 日期 | D1: =員工出勤日報表!A1 -> 46083 | J1: 備註
C2: 成本中心 | D2: 職務 | E2: 員編 | F2: 實際人數 | G2: 缺額 | H2: 新進人員 | I2: 離職人員
C3: 業務行政費用一 | D3: 處主管 | E3: 1 | F3: =各站員工名單!X63 -> 1 | G3: =E3-F3 -> 0 | L3: 吳佩珊
D4: 合計 | E4: =SUM(E3) -> 1 | F4: =SUM(F3) -> 1 | G4: =E4-F4 -> 0
C5: 業務行政費用二 | D5: 主任 | E5: 1 | F5: =各站員工名單!X64 -> 1 | G5: =E5-F5 -> 0 | L5: 林衍如
D6: 副管理師 | E6: 2 | F6: =各站員工名單!X80 -> 2 | G6: =E6-F6 -> 0 | L6: 蔡佩娟 | M6: 王宣詠
D7: 助理管理師 | E7: 2 | F7: =各站員工名單!X71+各站員工名單!X81 -> 2 | G7: =E7-F7 -> 0 | L7: 魏淑婷 | M7: 李美如
D8: 合計 | E8: =SUM(E5:E7) -> 5 | F8: =SUM(F5:F7) -> 5 | G8: =E8-F8 -> 0
C9: 電子商務部 | D9: 副管理師 | E9: 1 | F9: =各站員工名單!X65 -> 1 | G9: =E9-F9 -> 0 | L9: 范惟彥
D10: 合計 | E10: =SUM(E26:E26) -> 1 | F10: =SUM(F9) -> 1 | G10: =E10-F10 -> 0
C11: 北區業務部 | D11: 經理 | E11: 1 | F11: =各站員工名單!X67 -> 0 | G11: =E11-F11 -> 1 | L11: 張煜欣
D12: 業務專員 | E12: 0 | F12: =各站員工名單!X68 -> 0 | G12: =E12-F12 -> 0
D13: 合計 | E13: =SUM(E11:E12) -> 1 | F13: =SUM(F11:F12) -> 0 | G13: =E13-F13 -> 1
C14: 北區物流作業課 | D14: 主任 | E14: 1 | F14: =各站員工名單!X69 -> 1 | G14: =E14-F14 -> 0 | L14: 李建葳
D15: 合計 | E15: =E14 -> 1 | F15: =F14 -> 1 | G15: =E15-F15 -> 0
C16: 業務-燿華電子 | D16: 主任 | E16: 1 | F16: =各站員工名單!X72 -> 1 | G16: =E16-F16 -> 0 | L16: 張偉修
D17: 班長 | E17: 1 | F17: =各站員工名單!X73 -> 1 | G17: =E17-F17 -> 0 | L17: 王鈞平
D18: 堆高機人員(宜蘭廠) | E18: 1 | F18: =各站員工名單!X74 -> 1 | G18: =E18-F18 -> 0 | L18: 林炳宏
D19: 堆高機人員(土城廠) | E19: 3 | F19: =各站員工名單!X75 -> 3 | G19: =E19-F19 -> 0 | L19: 周正忠 | M19: 胡家祥 | N19: 陳嘉漢
D20: 司機人員 | E20: 1 | F20: =各站員工名單!X76 -> 1 | G20: =E20-F20 -> 0 | L20: 王立翔
D21: 合計 | E21: =SUM(E16:E20) -> 7 | F21: =SUM(F16:F20) -> 7 | G21: =E21-F21 -> 0
C22: 京元電子 | D22: 主任 | E22: 1 | F22: =各站員工名單!X77 -> 0 | G22: =E22-F22 -> 1
D23: 作業員 | E23: 1 | F23: =各站員工名單!X78 -> 2 | G23: =E23-F23 -> -1 | L23: 李武憲
D24: 合計 | E24: =SUM(E22:E23) -> 2 | F24: =SUM(F22:F23) -> 2 | G24: =E24-F24 -> 0
C25: 中區業務課 | D25: 業務-相如專案 | E25: 1 | F25: =各站員工名單!X79 -> 1 | G25: =E25-F25 -> 0 | L25: 劉相如
D26: 業務-献良專案 | E26: 1 | F26: =各站員工名單!X84 -> 1 | G26: =E26-F26 -> 0 | L26: 張簡献良
D27: 業務-敏耀專案 | E27: 1 | F27: =各站員工名單!X83 -> 1 | G27: =E27-F27 -> 0 | L27: 蘇敏耀
D28: 綜合服務專案 | E28: 1 | F28: =各站員工名單!X82 -> 1 | G28: =E28-F28 -> 0 | L28: 朱巧妏
D29: 業務廢棄物專案 | E29: 1 | F29: =各站員工名單!X85 -> 1 | G29: =E29-F29 -> 0 | L29: 陳文欽
D30: 合計 | E30: =SUM(E25:E29) -> 5 | F30: =SUM(F25:F29) -> 5 | G30: =E30-F30 -> 0
C31: 中區物流作業一課 | D31: 主管 | E31: 1 | F31: =各站員工名單!X86 -> 1 | G31: =E31-F31 -> 0 | L31: 周啟弘
D32: 合計 | E32: =E31 -> 1 | F32: =F31 -> 1 | G32: =E32-F32 -> 0
C33: 物流管理組 | D33: 組長 | E33: 0 | F33: =各站員工名單!X87 -> 0 | G33: =E33-F33 -> 0
D34: 壓縮車司機 | E34: 3 | F34: =各站員工名單!X88 -> 4 | G34: =E34-F34 -> -1 | L34: 李欣原 | M34: 王博鋐
D35: 35T 拖車司機 | E35: 2 | F35: =各站員工名單!X89 -> 2 | G35: =E35-F35 -> 0 | L35: 恩波
D36: 26T大貨車 | E36: 1 | F36: =各站員工名單!X90 -> 1 | G36: =E36-F36 -> 0 | L36: 邱明水
D37: 17T車司機 | E37: 6 | F37: =各站員工名單!X91 -> 5 | G37: =E37-F37 -> 1 | L37: 許國賓 | M37: 林倫揚 | N37: 陳品紘 | O37: 梁國晉
D38: 7.7及7.4貨車 | E38: 2 | F38: =各站員工名單!X92+各站員工名單!X93 -> 1 | G38: =E38-F38 -> 1 | L38: 楊財綜
D39: 3.5噸司機 | E39: 0 | F39: =各站員工名單!X94 -> 0 | G39: =E39-F39 -> 0
D40: 副管理師 | E40: 1 | F40: =各站員工名單!X95 -> 0 | G40: =E40-F40 -> 1
...

Sheet 資料
G1: 到職 | I1: 離職
A2: 通知日 | B2: 事業處 | C2: 部門 | D2: 職位(務) | E2: 工號 | F2: 姓名 | G2: 年份 | H2: 月份 | I2: 年份 | J2: 月份 | K2: 到職日 | L2: 離職日 | M2: 在職天數 | O2: 未滿90天
A3: 41244 | B3: 業務開發處 | C3: 文山專案 | D3: 作業員 | E3: 無 | F3: 高振駸 | G3: =IF(K3="",0,YEAR(K3)) -> 2012 | H3: =IF(K3="",0,MONTH(K3)) -> 12 | I3: =IF(L3="",0,YEAR(K3)) -> 2012 | J3: =IF(L3="",0,MONTH(L3)) -> 12 | K3: 41244 | L3: 41244 | M3: =IF(L3="",0,L3-K3+1) -> 1 | O3: =IF(M3<91,"V","") -> V
B4: 營運管理處 | C4: 營運管理處 | D4: 儲備幹部 | E4: 02204 | F4: 廖柏鈞 | G4: =IF(K4="",0,YEAR(K4)) -> 2012 | H4: =IF(K4="",0,MONTH(K4)) -> 12 | I4: =IF(L4="",0,YEAR(K4)) -> 0 | J4: =IF(L4="",0,MONTH(L4)) -> 0 | K4: 41246 | M4: =IF(L4="",0,L4-K4+1) -> 0 | O4: =IF(M4<91,"V","") -> V
B5: 再生處理處 | C5: 喬翔分選課 | D5: 計時作業員 | F5: 廖玉梅 | G5: =IF(K5="",0,YEAR(K5)) -> 2012 | H5: =IF(K5="",0,MONTH(K5)) -> 12 | I5: =IF(L5="",0,YEAR(K5)) -> 0 | J5: =IF(L5="",0,MONTH(L5)) -> 0 | K5: 41250 | M5: =IF(L5="",0,L5-K5+1) -> 0 | O5: =IF(M5<91,"V","") -> V
A6: 41244 | B6: 業務開發處 | C6: 文山專案 | D6: 作業員 | E6: 無 | F6: 江志隆 | G6: =IF(K6="",0,YEAR(K6)) -> 2012 | H6: =IF(K6="",0,MONTH(K6)) -> 12 | I6: =IF(L6="",0,YEAR(K6)) -> 2012 | J6: =IF(L6="",0,MONTH(L6)) -> 12 | K6: 41254 | L6: 41254 | M6: =IF(L6="",0,L6-K6+1) -> 1 | O6: =IF(M6<91,"V","") -> V
B7: 業務開發處 | C7: 友達-資收區(七星) | D7: 作業員 | E7: 01880 | F7: 周氏善 | G7: =IF(K7="",0,YEAR(K7)) -> 2011 | H7: =IF(K7="",0,MONTH(K7)) -> 9 | I7: =IF(L7="",0,YEAR(K7)) -> 2011 | J7: =IF(L7="",0,MONTH(L7)) -> 12 | K7: 40787 | L7: 41244 | M7: =IF(L7="",0,L7-K7+1) -> 458 | O7: =IF(M7<91,"V","")
B8: 業務開發處 | C8: 友達-后里包材清潔區 | D8: 作業員 | E8: 02008 | F8: 邵紫廷 | G8: =IF(K8="",0,YEAR(K8)) -> 2012 | H8: =IF(K8="",0,MONTH(K8)) -> 3 | I8: =IF(L8="",0,YEAR(K8)) -> 2012 | J8: =IF(L8="",0,MONTH(L8)) -> 12 | K8: 40969 | L8: 41253 | M8: =IF(L8="",0,L8-K8+1) -> 285 | O8: =IF(M8<91,"V","")
B9: 再生處理處 | C9: 處理課 | D9: 外場人員 | E9: 01598 | F9: 李元夆 | G9: =IF(K9="",0,YEAR(K9)) -> 2010 | H9: =IF(K9="",0,MONTH(K9)) -> 7 | I9: =IF(L9="",0,YEAR(K9)) -> 2010 | J9: =IF(L9="",0,MONTH(L9)) -> 12 | K9: 40364 | L9: 41251 | M9: =IF(L9="",0,L9-K9+1) -> 888 | O9: =IF(M9<91,"V","")
B10: 再生處理處 | C10: 分選課 | D10: 外勞 | E10: 01676 | F10: 查那猜 | G10: =IF(K10="",0,YEAR(K10)) -> 2010 | H10: =IF(K10="",0,MONTH(K10)) -> 9 | I10: =IF(L10="",0,YEAR(K10)) -> 2010 | J10: =IF(L10="",0,MONTH(L10)) -> 12 | K10: 40449 | L10: 41253 | M10: =IF(L10="",0,L10-K10+1) -> 805 | O10: =IF(M10<91,"V","")
A11: 40909 | B11: 營運管理處 | C11: 新竹站 | D11: 外場人員 | E11: 02189 | F11: 潘青宏 | G11: =IF(K11="",0,YEAR(K11)) -> 2012 | H11: =IF(K11="",0,MONTH(K11)) -> 10 | I11: =IF(L11="",0,YEAR(K11)) -> 2012 | J11: =IF(L11="",0,MONTH(L11)) -> 1 | K11: 41193 | L11: 41277 | M11: =IF(L11="",0,L11-K11+1) -> 85 | O11: =IF(M11<91,"V","") -> V
B12: 策略管理處 | C12: 人資策略組 | D12: 工讀生 | E12: 02195 | F12: 蘇若綺 | G12: =IF(K12="",0,YEAR(K12)) -> 2012 | H12: =IF(K12="",0,MONTH(K12)) -> 11 | I12: =IF(L12="",0,YEAR(K12)) -> 2012 | J12: =IF(L12="",0,MONTH(L12)) -> 1 | K12: 41214 | L12: 41276 | M12: =IF(L12="",0,L12-K12+1) -> 63 | O12: =IF(M12<91,"V","") -> V
B13: 營運管理處 | C13: 員林新站 | D13: 外場人員 | E13: X | F13: 陳志佳 | G13: =IF(K13="",0,YEAR(K13)) -> 2012 | H13: =IF(K13="",0,MONTH(K13)) -> 1 | I13: =IF(L13="",0,YEAR(K13)) -> 2012 | J13: =IF(L13="",0,MONTH(L13)) -> 1 | K13: 40912 | L13: 40912 | M13: =IF(L13="",0,L13-K13+1) -> 1 | O13: =IF(M13<91,"V","") -> V
B14: 業務開發處 | C14: 文山專案 | D14: 作業員 | E14: 02054 | F14: 溫壽昌 | G14: =IF(K14="",0,YEAR(K14)) -> 2011 | H14: =IF(K14="",0,MONTH(K14)) -> 3 | I14: =IF(L14="",0,YEAR(K14)) -> 2011 | J14: =IF(L14="",0,MONTH(L14)) -> 1 | K14: 40609 | L14: 41281 | M14: =IF(L14="",0,L14-K14+1) -> 673 | O14: =IF(M14<91,"V","")
B15: 業務開發處 | C15: 夢時代統包 | D15: 外場人員 | E15: 02197 | F15: 鍾宏儒 | G15: =IF(K15="",0,YEAR(K15)) -> 2012 | H15: =IF(K15="",0,MONTH(K15)) -> 11 | I15: =IF(L15="",0,YEAR(K15)) -> 2012 | J15: =IF(L15="",0,MONTH(L15)) -> 1 | K15: 41215 | L15: 41284 | M15: =IF(L15="",0,L15-K15+1) -> 70 | O15: =IF(M15<91,"V","") -> V
B16: 國際事業處 | C16: 國際事業處 | D16: 副理 | E16: 00062 | F16: 宋祈全 | G16: =IF(K16="",0,YEAR(K16)) -> 2004 | H16: =IF(K16="",0,MONTH(K16)) -> 8 | I16: =IF(L16="",0,YEAR(K16)) -> 2004 | J16: =IF(L16="",0,MONTH(L16)) -> 1 | K16: 38222 | L16: 41295 | M16: =IF(L16="",0,L16-K16+1) -> 3074 | O16: =IF(M16<91,"V","")
B17: 營運管理處 | C17: 彰興站 | D17: 夾子車司機 | E17: 02199 | F17: 蔡渙凱 | G17: =IF(K17="",0,YEAR(K17)) -> 2012 | H17: =IF(K17="",0,MONTH(K17)) -> 11 | I17: =IF(L17="",0,YEAR(K17)) -> 2012 | J17: =IF(L17="",0,MONTH(L17)) -> 1 | K17: 41234 | L17: 41297 | M17: =IF(L17="",0,L17-K17+1) -> 64 | O17: =IF(M17<91,"V","") -> V
B18: 業務開發處 | C18: 文山專案 | D18: 短期作業員 | E18: X | F18: 梁云佳 | G18: =IF(K18="",0,YEAR(K18)) -> 2013 | H18: =IF(K18="",0,MONTH(K18)) -> 1 | I18: =IF(L18="",0,YEAR(K18)) -> 2013 | J18: =IF(L18="",0,MONTH(L18)) -> 1 | K18: 41298 | L18: 41298 | M18: =IF(L18="",0,L18-K18+1) -> 1 | O18: =IF(M18<91,"V","") -> V
B19: 業務開發處 | C19: 文山專案 | D19: 作業員 | E19: 02228 | F19: 武祥麟 | G19: =IF(K19="",0,YEAR(K19)) -> 2013 | H19: =IF(K19="",0,MONTH(K19)) -> 1 | I19: =IF(L19="",0,YEAR(K19)) -> 2013 | J19: =IF(L19="",0,MONTH(L19)) -> 1 | K19: 41299 | L19: 41302 | M19: =IF(L19="",0,L19-K19+1) -> 4 | O19: =IF(M19<91,"V","") -> V
B20: 營運管理處 | C20: 員林三信站 | D20: 外場人員 | E20: X | F20: 黃偉銘 | G20: =IF(K20="",0,YEAR(K20)) -> 2013 | H20: =IF(K20="",0,MONTH(K20)) -> 1 | I20: =IF(L20="",0,YEAR(K20)) -> 2013 | J20: =IF(L20="",0,MONTH(L20)) -> 1 | K20: 41302 | L20: 41302 | M20: =IF(L20="",0,L20-K20+1) -> 1 | O20: =IF(M20<91,"V","") -> V
B21: 業務開發處 | C21: 文山專案 | D21: 短期作業員 | E21: 02227 | F21: 白雨晨 | G21: =IF(K21="",0,YEAR(K21)) -> 2013 | H21: =IF(K21="",0,MONTH(K21)) -> 1 | I21: =IF(L21="",0,YEAR(K21)) -> 2013 | J21: =IF(L21="",0,MONTH(L21)) -> 1 | K21: 41298 | L21: 41305 | M21: =IF(L21="",0,L21-K21+1) -> 8 | O21: =IF(M21<91,"V","") -> V
B22: 營運管理處 | C22: 新竹站 | D22: 外場人員 | F22: 黃守仁 | G22: =IF(K22="",0,YEAR(K22)) -> 2012 | H22: =IF(K22="",0,MONTH(K22)) -> 8 | I22: =IF(L22="",0,YEAR(K22)) -> 2012 | J22: =IF(L22="",0,MONTH(L22)) -> 2 | K22: 41122 | L22: 41306 | M22: =IF(L22="",0,L22-K22+1) -> 185 | O22: =IF(M22<91,"V","")
B23: 業務開發處 | C23: 文山專案 | D23: 堆高機 | E23: 02211 | F23: 陳盈昌 | G23: =IF(K23="",0,YEAR(K23)) -> 2012 | H23: =IF(K23="",0,MONTH(K23)) -> 12 | I23: =IF(L23="",0,YEAR(K23)) -> 2012 | J23: =IF(L23="",0,MONTH(L23)) -> 2 | K23: 41270 | L23: 41311 | M23: =IF(L23="",0,L23-K23+1) -> 42 | O23: =IF(M23<91,"V","") -> V
B24: 營運管理處 | C24: 土城站 | D24: 外場人員 | F24: 邱子豪 | G24: =IF(K24="",0,YEAR(K24)) -> 2010 | H24: =IF(K24="",0,MONTH(K24)) -> 10 | I24: =IF(L24="",0,YEAR(K24)) -> 2010 | J24: =IF(L24="",0,MONTH(L24)) -> 2 | K24: 40458 | L24: 41320 | M24: =IF(L24="",0,L24-K24+1) -> 863 | O24: =IF(M24<91,"V","")
B25: 業務開發處 | C25: 夢時代統包 | D25: 外場人員 | F25: 吳秉達 | G25: =IF(K25="",0,YEAR(K25)) -> 2013 | H25: =IF(K25="",0,MONTH(K25)) -> 1 | I25: =IF(L25="",0,YEAR(K25)) -> 2013 | J25: =IF(L25="",0,MONTH(L25)) -> 2 | K25: 41285 | L25: 41313 | M25: =IF(L25="",0,L25-K25+1) -> 29 | O25: =IF(M25<91,"V","") -> V
B26: 營運管理處 | C26: 新竹站 | D26: 3/5T司機 | E26: X | F26: 薛建誠 | G26: =IF(K26="",0,YEAR(K26)) -> 2013 | H26: =IF(K26="",0,MONTH(K26)) -> 2 | I26: =IF(L26="",0,YEAR(K26)) -> 2013 | J26: =IF(L26="",0,MONTH(L26)) -> 2 | K26: 41323 | L26: 41323 | M26: =IF(L26="",0,L26-K26+1) -> 1 | O26: =IF(M26<91,"V","") -> V
B27: 業務開發處 | C27: 明基北部專案(龍潭) | D27: 外場人員 | F27: 徐清富 | G27: =IF(K27="",0,YEAR(K27)) -> 2012 | H27: =IF(K27="",0,MONTH(K27)) -> 7 | I27: =IF(L27="",0,YEAR(K27)) -> 2012 | J27: =IF(L27="",0,MONTH(L27)) -> 2 | K27: 41106 | L27: 41320 | M27: =IF(L27="",0,L27-K27+1) -> 215 | O27: =IF(M27<91,"V","")
B28: 業務開發處 | C28: 明基北部專案(龍潭) | D28: 外場人員 | F28: 張文山 | G28: =IF(K28="",0,YEAR(K28)) -> 2012 | H28: =IF(K28="",0,MONTH(K28)) -> 7 | I28: =IF(L28="",0,YEAR(K28)) -> 2012 | J28: =IF(L28="",0,MONTH(L28)) -> 2 | K28: 41107 | L28: 41320 | M28: =IF(L28="",0,L28-K28+1) -> 214 | O28: =IF(M28<91,"V","")
B29: 業務開發處 | C29: 文山專案 | D29: 晚班堆高機 | E29: 02157 | F29: 巫信融 | G29: =IF(K29="",0,YEAR(K29)) -> 2012 | H29: =IF(K29="",0,MONTH(K29)) -> 8 | I29: =IF(L29="",0,YEAR(K29)) -> 2012 | J29: =IF(L29="",0,MONTH(L29)) -> 2 | K29: 41122 | L29: 41325 | M29: =IF(L29="",0,L29-K29+1) -> 204 | O29: =IF(M29<91,"V","")
B30: 業務開發處 | C30: 中部資收 | D30: 外場人員 | F30: 許明河 | G30: =IF(K30="",0,YEAR(K30)) -> 2012 | H30: =IF(K30="",0,MONTH(K30)) -> 2 | I30: =IF(L30="",0,YEAR(K30)) -> 2012 | J30: =IF(L30="",0,MONTH(L30)) -> 2 | K30: 40940 | L30: 41327 | M30: =IF(L30="",0,L30-K30+1) -> 388 | O30: =IF(M30<91,"V","")
B31: 業務開發處 | C31: 安定倉庫 | D31: 助理會計 | E31: 02232 | F31: 鄭怡婷 | G31: =IF(K31="",0,YEAR(K31)) -> 2013 | H31: =IF(K31="",0,MONTH(K31)) -> 2 | I31: =IF(L31="",0,YEAR(K31)) -> 2013 | J31: =IF(L31="",0,MONTH(L31)) -> 2 | K31: 41323 | L31: 41327 | M31: =IF(L31="",0,L31-K31+1) -> 5 | O31: =IF(M31<91,"V","") -> V
B32: 業務開發處 | C32: 明基北部(龍潭) | D32: 外場人員 | F32: 朱逸仙 | G32: =IF(K32="",0,YEAR(K32)) -> 2012 | H32: =IF(K32="",0,MONTH(K32)) -> 7 | I32: =IF(L32="",0,YEAR(K32)) -> 2012 | J32: =IF(L32="",0,MONTH(L32)) -> 2 | K32: 41114 | L32: 41328 | M32: =IF(L32="",0,L32-K32+1) -> 215 | O32: =IF(M32<91,"V","")
B33: 業務開發處 | C33: 友達-后里包材清潔區 | D33: 助理會計 | F33: 吳采融 | G33: =IF(K33="",0,YEAR(K33)) -> 2011 | H33: =IF(K33="",0,MONTH(K33)) -> 1 | I33: =IF(L33="",0,YEAR(K33)) -> 2011 | J33: =IF(L33="",0,MONTH(L33)) -> 2 | K33: 40561 | L33: 41330 | M33: =IF(L33="",0,L33-K33+1) -> 770 | O33: =IF(M33<91,"V","")
B34: 業務開發處 | C34: 中部倉庫 | D34: 作業員 | F34: 黃永騰 | G34: =IF(K34="",0,YEAR(K34)) -> 2013 | H34: =IF(K34="",0,MONTH(K34)) -> 2 | I34: =IF(L34="",0,YEAR(K34)) -> 2013 | J34: =IF(L34="",0,MONTH(L34)) -> 2 | K34: 41327 | L34: 41328 | M34: =IF(L34="",0,L34-K34+1) -> 2 | O34: =IF(M34<91,"V","") -> V
B35: 業務開發處 | C35: 高雄仁武倉庫 | D35: 外場人員 | E35: 02084 | F35: 林欣宏 | G35: =IF(K35="",0,YEAR(K35)) -> 2012 | H35: =IF(K35="",0,MONTH(K35)) -> 5 | I35: =IF(L35="",0,YEAR(K35)) -> 2012 | J35: =IF(L35="",0,MONTH(L35)) -> 2 | K35: 41045 | L35: 41333 | M35: =IF(L35="",0,L35-K35+1) -> 289 | O35: =IF(M35<91,"V","")
B36: 國際事業處 | C36: 國際事業處 | D36: 副課長 | E36: 01313 | F36: 賴娜慧 | G36: =IF(K36="",0,YEAR(K36)) -> 2009 | H36: =IF(K36="",0,MONTH(K36)) -> 8 | I36: =IF(L36="",0,YEAR(K36)) -> 2009 | J36: =IF(L36="",0,MONTH(L36)) -> 2 | K36: 40028 | L36: 41333 | M36: =IF(L36="",0,L36-K36+1) -> 1306 | O36: =IF(M36<91,"V","")
B37: 再生處理處 | C37: 喬翔分選 | D37: 作業員 | E37: 01846 | F37: 鄭秀蘭 | G37: =IF(K37="",0,YEAR(K37)) -> 2011 | H37: =IF(K37="",0,MONTH(K37)) -> 7 | I37: =IF(L37="",0,YEAR(K37)) -> 2011 | J37: =IF(L37="",0,MONTH(L37)) -> 2 | K37: 40730 | L37: 41333 | M37: =IF(L37="",0,L37-K37+1) -> 604 | O37: =IF(M37<91,"V","")
B38: 再生處理處 | C38: 全興處理課 | D38: 外場人員 | E38: 01419 | F38: 李建盛 | G38: =IF(K38="",0,YEAR(K38)) -> 2009 | H38: =IF(K38="",0,MONTH(K38)) -> 12 | I38: =IF(L38="",0,YEAR(K38)) -> 2009 | J38: =IF(L38="",0,MONTH(L38)) -> 2 | K38: 40164 | L38: 41333 | M38: =IF(L38="",0,L38-K38+1) -> 1170 | O38: =IF(M38<91,"V","")
B39: 再生處理處 | C39: 全興分選課 | D39: 作業員 | E39: 02166 | F39: 替瓦 | G39: =IF(K39="",0,YEAR(K39)) -> 2012 | H39: =IF(K39="",0,MONTH(K39)) -> 8 | I39: =IF(L39="",0,YEAR(K39)) -> 2012 | J39: =IF(L39="",0,MONTH(L39)) -> 2 | K39: 41144 | L39: 41333 | M39: =IF(L39="",0,L39-K39+1) -> 190 | O39: =IF(M39<91,"V","")
B40: 業務開發處 | C40: 安定倉庫 | D40: 助理會計 | F40: 郭怡婷 | G40: =IF(K40="",0,YEAR(K40)) -> 2010 | H40: =IF(K40="",0,MONTH(K40)) -> 3 | I40: =IF(L40="",0,YEAR(K40)) -> 2010 | J40: =IF(L40="",0,MONTH(L40)) -> 2 | K40: 40264 | L40: 41315 | M40: =IF(L40="",0,L40-K40+1) -> 1052 | O40: =IF(M40<91,"V","")
...

Sheet 單位離職率統計
J1: 4
A2: 事業處 | B2: 室/站/專案 | E2: =YEAR(E3)&-MONTH(E3) -> 2013-4
E3: 41365 | F3: 41394 | G3: 當月 | H3: 當月 | J3: 當月 | L3: 當月 | N3: 當月 流動率
E4: 單位總人數 | F4: 單位總人數 | G4: 新進人員人數 | H4: 人員調動 | J4: 離職人數 | L4: 離職率
H5: 增加 | I5: 減少 | J5: 未滿90天 | K5: 全部 | L5: 未滿90天 | M5: 全部
A6: =B6 -> #REF! | B6: =#REF! -> #REF! | E6: 7 | F6: 7 | G6: =COUNTIFS(資料!$C:$C,B6,資料!$G:$G,"2013",資料!$H:$H,"4") -> 0 | H6: 0 | I6: 0 | J6: =COUNTIFS(資料!$C:$C,B6,資料!$I:$I,"2013",資料!$J:$J,"4",資料!$O:$O,"V") -> 0 | K6: =COUNTIFS(資料!$C:$C,B6,資料!$I:$I,"2013",資料!$J:$J,"4") -> 0 | L6: =J6/AVERAGE(E6,F6) -> 0 | M6: =K6/AVERAGE(E6,F6) -> 0 | N6: =(G6+K6)/AVERAGE(E6,F6) -> 0
A7: =B7 -> #REF! | B7: =#REF! -> #REF! | E7: 4 | F7: 5 | G7: =COUNTIFS(資料!$C:$C,B7,資料!$G:$G,"2013",資料!$H:$H,"4") -> 0 | H7: 0 | I7: 0 | J7: =COUNTIFS(資料!$C:$C,B7,資料!$I:$I,"2013",資料!$J:$J,"4",資料!$O:$O,"V") -> 0 | K7: =COUNTIFS(資料!$C:$C,B7,資料!$I:$I,"2013",資料!$J:$J,"4") -> 0 | L7: =J7/AVERAGE(E7,F7) -> 0 | M7: =K7/AVERAGE(E7,F7) -> 0 | N7: =(G7+K7)/AVERAGE(E7,F7) -> 0
A8: =B8 -> #REF! | B8: =#REF! -> #REF! | E8: 4 | F8: 4 | G8: =COUNTIFS(資料!$C:$C,B8,資料!$G:$G,"2013",資料!$H:$H,"4") -> 0 | H8: 0 | I8: 0 | J8: =COUNTIFS(資料!$C:$C,B8,資料!$I:$I,"2013",資料!$J:$J,"4",資料!$O:$O,"V") -> 0 | K8: =COUNTIFS(資料!$C:$C,B8,資料!$I:$I,"2013",資料!$J:$J,"4") -> 0 | L8: =J8/AVERAGE(E8,F8) -> 0 | M8: =K8/AVERAGE(E8,F8) -> 0 | N8: =(G8+K8)/AVERAGE(E8,F8) -> 0
A9: 財務處 | B9: =#REF! -> #REF! | E9: 1 | F9: 1 | G9: =COUNTIFS(資料!$C:$C,A9,資料!$G:$G,"2013",資料!$H:$H,"4") -> 0 | H9: 0 | I9: 0 | J9: =COUNTIFS(資料!$C:$C,B9,資料!$I:$I,"2013",資料!$J:$J,"4",資料!$O:$O,"V") -> 0 | K9: =COUNTIFS(資料!$C:$C,B9,資料!$I:$I,"2013",資料!$J:$J,"4") -> 0 | L9: =J9/AVERAGE(E9,F9) -> 0 | M9: =K9/AVERAGE(E9,F9) -> 0 | N9: =(G9+K9)/AVERAGE(E9,F9) -> 0
B10: =#REF! -> #REF! | E10: 3 | F10: 3 | J10: =COUNTIFS(資料!$C:$C,B10,資料!$I:$I,"2013",資料!$J:$J,"4",資料!$O:$O,"V") -> 0 | K10: =COUNTIFS(資料!$C:$C,B10,資料!$I:$I,"2013",資料!$J:$J,"4") -> 0 | L10: =J10/AVERAGE(E10,F10) -> 0 | M10: =K10/AVERAGE(E10,F10) -> 0 | N10: =(G10+K10)/AVERAGE(E10,F10) -> 0
B11: =#REF! -> #REF! | E11: 9 | F11: 9 | J11: =COUNTIFS(資料!$C:$C,B11,資料!$I:$I,"2013",資料!$J:$J,"4",資料!$O:$O,"V") -> 0 | K11: =COUNTIFS(資料!$C:$C,B11,資料!$I:$I,"2013",資料!$J:$J,"4") -> 0 | L11: =J11/AVERAGE(E11,F11) -> 0 | M11: =K11/AVERAGE(E11,F11) -> 0 | N11: =(G11+K11)/AVERAGE(E11,F11) -> 0
B12: =#REF! -> #REF! | E12: 3 | F12: 3 | J12: =COUNTIFS(資料!$C:$C,B12,資料!$I:$I,"2013",資料!$J:$J,"4",資料!$O:$O,"V") -> 0 | K12: =COUNTIFS(資料!$C:$C,B12,資料!$I:$I,"2013",資料!$J:$J,"4") -> 0 | L12: =J12/AVERAGE(E12,F12) -> 0 | M12: =K12/AVERAGE(E12,F12) -> 0 | N12: =(G12+K12)/AVERAGE(E12,F12) -> 0
A13: 策略管理處 | B13: =#REF! -> #REF! | E13: 3 | F13: 3 | G13: =COUNTIFS(資料!$C:$C,B13,資料!$G:$G,"2013",資料!$H:$H,"4") -> 0 | H13: 0 | I13: 0 | J13: =COUNTIFS(資料!$C:$C,B13,資料!$I:$I,"2013",資料!$J:$J,"4",資料!$O:$O,"V") -> 0 | K13: =COUNTIFS(資料!$C:$C,B13,資料!$I:$I,"2013",資料!$J:$J,"4") -> 0 | L13: =J13/AVERAGE(E13,F13) -> 0 | M13: =K13/AVERAGE(E13,F13) -> 0 | N13: =(G13+K13)/AVERAGE(E13,F13) -> 0
B14: =#REF! -> #REF! | E14: 2 | F14: 2 | G14: =COUNTIFS(資料!$C:$C,B14,資料!$G:$G,"2013",資料!$H:$H,"4") -> 0 | H14: 0 | I14: 0 | J14: =COUNTIFS(資料!$C:$C,B14,資料!$I:$I,"2013",資料!$J:$J,"4",資料!$O:$O,"V") -> 0 | K14: =COUNTIFS(資料!$C:$C,B14,資料!$I:$I,"2013",資料!$J:$J,"4") -> 0 | L14: =J14/AVERAGE(E14,F14) -> 0 | M14: =K14/AVERAGE(E14,F14) -> 0 | N14: =(G14+K14)/AVERAGE(E14,F14) -> 0
B15: =#REF! -> #REF! | E15: 5 | F15: 6 | G15: =COUNTIFS(資料!$C:$C,B15,資料!$G:$G,"2013",資料!$H:$H,"4") -> 0 | H15: 0 | I15: 0 | J15: =COUNTIFS(資料!$C:$C,B15,資料!$I:$I,"2013",資料!$J:$J,"4",資料!$O:$O,"V") -> 0 | K15: =COUNTIFS(資料!$C:$C,B15,資料!$I:$I,"2013",資料!$J:$J,"4") -> 0 | L15: =J15/AVERAGE(E15,F15) -> 0 | M15: =K15/AVERAGE(E15,F15) -> 0 | N15: =(G15+K15)/AVERAGE(E15,F15) -> 0
B16: =#REF! -> #REF! | E16: 2 | F16: 2 | G16: =COUNTIFS(資料!$C:$C,B16,資料!$G:$G,"2013",資料!$H:$H,"4") -> 0 | H16: 0 | I16: 0 | J16: =COUNTIFS(資料!$C:$C,B16,資料!$I:$I,"2013",資料!$J:$J,"4",資料!$O:$O,"V") -> 0 | K16: =COUNTIFS(資料!$C:$C,B16,資料!$I:$I,"2013",資料!$J:$J,"4") -> 0 | L16: =J16/AVERAGE(E16,F16) -> 0 | M16: =K16/AVERAGE(E16,F16) -> 0 | N16: =(G16+K16)/AVERAGE(E16,F16) -> 0
B17: =#REF! -> #REF! | E17: 5 | F17: 5 | G17: =COUNTIFS(資料!$C:$C,B17,資料!$G:$G,"2013",資料!$H:$H,"4") -> 0 | H17: 0 | I17: 0 | J17: =COUNTIFS(資料!$C:$C,B17,資料!$I:$I,"2013",資料!$J:$J,"4",資料!$O:$O,"V") -> 0 | K17: =COUNTIFS(資料!$C:$C,B17,資料!$I:$I,"2013",資料!$J:$J,"4") -> 0 | L17: =J17/AVERAGE(E17,F17) -> 0 | M17: =K17/AVERAGE(E17,F17) -> 0 | N17: =(G17+K17)/AVERAGE(E17,F17) -> 0
A18: 業務開發處 | B18: 處主管 | E18: 1 | F18: 1 | G18: =COUNTIFS(資料!$C:$C,B18,資料!$G:$G,"2013",資料!$H:$H,"4") -> 0 | H18: 0 | I18: 0 | J18: =COUNTIFS(資料!$C:$C,B18,資料!$I:$I,"2013",資料!$J:$J,"4",資料!$O:$O,"V") -> 0 | K18: =COUNTIFS(資料!$C:$C,B18,資料!$I:$I,"2013",資料!$J:$J,"4") -> 0 | L18: =J18/AVERAGE(E18,F18) -> 0 | M18: =K18/AVERAGE(E18,F18) -> 0 | N18: =(G18+K18)/AVERAGE(E18,F18) -> 0
B19: 業務處行政室 | E19: 6 | F19: 6 | G19: =COUNTIFS(資料!$C:$C,B19,資料!$G:$G,"2013",資料!$H:$H,"4") -> 0 | H19: 0 | I19: 0 | J19: =COUNTIFS(資料!$C:$C,B19,資料!$I:$I,"2013",資料!$J:$J,"4",資料!$O:$O,"V") -> 0 | K19: =COUNTIFS(資料!$C:$C,B19,資料!$I:$I,"2013",資料!$J:$J,"4") -> 0 | L19: =J19/AVERAGE(E19,F19) -> 0 | M19: =K19/AVERAGE(E19,F19) -> 0 | N19: =(G19+K19)/AVERAGE(E19,F19) -> 0
B20: 中區市場開發部 | E20: 3 | F20: 3 | G20: =COUNTIFS(資料!$C:$C,B20,資料!$G:$G,"2013",資料!$H:$H,"4") -> 0 | H20: 0 | I20: 0 | J20: =COUNTIFS(資料!$C:$C,B20,資料!$I:$I,"2013",資料!$J:$J,"4",資料!$O:$O,"V") -> 0 | K20: =COUNTIFS(資料!$C:$C,B20,資料!$I:$I,"2013",資料!$J:$J,"4") -> 0 | L20: =J20/AVERAGE(E20,F20) -> 0 | M20: =K20/AVERAGE(E20,F20) -> 0 | N20: =(G20+K20)/AVERAGE(E20,F20) -> 0
B21: 中區-倉儲物流管理部 | C21: 主任 | E21: 1 | F21: 1 | G21: =COUNTIFS(資料!$C:$C,B21,資料!$G:$G,"2013",資料!$H:$H,"4") -> 0 | H21: 0 | I21: 0 | J21: =COUNTIFS(資料!$C:$C,B21,資料!$I:$I,"2013",資料!$J:$J,"4",資料!$O:$O,"V") -> 0 | K21: =COUNTIFS(資料!$C:$C,C21,資料!$I:$I,"2013",資料!$J:$J,"4") -> 0 | L21: =J21/AVERAGE(E21,F21) -> 0 | M21: =K21/AVERAGE(E21,F21) -> 0 | N21: =(G21+K21)/AVERAGE(E21,F21) -> 0
D22: 中部物流管理組 | E22: 11 | F22: 11 | G22: =COUNTIFS(資料!$C:$C,D22,資料!$G:$G,"2013",資料!$H:$H,"4") -> 0 | H22: 0 | I22: 0 | J22: =COUNTIFS(資料!$C:$C,B22,資料!$I:$I,"2013",資料!$J:$J,"4",資料!$O:$O,"V") -> 0 | K22: =COUNTIFS(資料!$C:$C,D22,資料!$I:$I,"2013",資料!$J:$J,"4") -> 0 | L22: =J22/AVERAGE(E22,F22) -> 0 | M22: =K22/AVERAGE(E22,F22) -> 0 | N22: =(G22+K22)/AVERAGE(E22,F22) -> 0
D23: 中部倉庫 | E23: 6 | F23: 8 | G23: =COUNTIFS(資料!$C:$C,D23,資料!$G:$G,"2013",資料!$H:$H,"4") -> 1 | H23: 1 | I23: 0 | J23: =COUNTIFS(資料!$C:$C,D23,資料!$I:$I,"2013",資料!$J:$J,"4",資料!$O:$O,"V") -> 0 | K23: =COUNTIFS(資料!$C:$C,D23,資料!$I:$I,"2013",資料!$J:$J,"4") -> 0 | L23: =J23/AVERAGE(E23,F23) -> 0 | M23: =K23/AVERAGE(E23,F23) -> 0 | N23: =(G23+K23)/AVERAGE(E23,F23) -> 0.14285714
C24: 文山專案 | D24: 文山專案 | E24: 21 | F24: 20 | G24: =COUNTIFS(資料!$C:$C,D24,資料!$G:$G,"2013",資料!$H:$H,"4") -> 0 | H24: 0 | I24: 1 | J24: =COUNTIFS(資料!$C:$C,D24,資料!$I:$I,"2013",資料!$J:$J,"4",資料!$O:$O,"V") -> 0 | K24: =COUNTIFS(資料!$C:$C,D24,資料!$I:$I,"2013",資料!$J:$J,"4") -> 0 | L24: =J24/AVERAGE(E24,F24) -> 0 | M24: =K24/AVERAGE(E24,F24) -> 0 | N24: =(G24+K24)/AVERAGE(E24,F24) -> 0
D25: 人力仲介 | E25: 0 | F25: 0 | G25: =COUNTIFS(資料!$C:$C,D25,資料!$G:$G,"2013",資料!$H:$H,"4") -> 0 | H25: 0 | I25: 0 | J25: =COUNTIFS(資料!$C:$C,D25,資料!$I:$I,"2013",資料!$J:$J,"4",資料!$O:$O,"V") -> 0 | K25: =COUNTIFS(資料!$C:$C,D25,資料!$I:$I,"2013",資料!$J:$J,"4") -> 0 | L25: 0 | M25: 0 | N25: 0
C26: 輔祥專案 | D26: 輔祥專案 | E26: 2 | F26: 2 | G26: =COUNTIFS(資料!$C:$C,D26,資料!$G:$G,"2013",資料!$H:$H,"4") -> 0 | H26: 0 | I26: 0 | J26: =COUNTIFS(資料!$C:$C,D26,資料!$I:$I,"2013",資料!$J:$J,"4",資料!$O:$O,"V") -> 0 | K26: =COUNTIFS(資料!$C:$C,D26,資料!$I:$I,"2013",資料!$J:$J,"4") -> 0 | L26: =J26/AVERAGE(E26,F26) -> 0 | M26: =K26/AVERAGE(E26,F26) -> 0 | N26: =(G26+K26)/AVERAGE(E26,F26) -> 0
C27: 友達專案 | D27: 副主任 | E27: 2 | F27: 2 | G27: =COUNTIFS(資料!$C:$C,D27,資料!$G:$G,"2013",資料!$H:$H,"4") -> 0 | H27: 0 | I27: 0 | J27: =COUNTIFS(資料!$C:$C,D27,資料!$I:$I,"2013",資料!$J:$J,"4",資料!$O:$O,"V") -> 0 | K27: =COUNTIFS(資料!$C:$C,D27,資料!$I:$I,"2013",資料!$J:$J,"4") -> 0 | L27: =J27/AVERAGE(E27,F27) -> 0 | M27: =K27/AVERAGE(E27,F27) -> 0 | N27: =(G27+K27)/AVERAGE(E27,F27) -> 0
D28: 友達-資收區(一、二期) | E28: 9 | F28: 9 | G28: =COUNTIFS(資料!$C:$C,D28,資料!$G:$G,"2013",資料!$H:$H,"4") -> 0 | H28: 0 | I28: 0 | J28: =COUNTIFS(資料!$C:$C,D28,資料!$I:$I,"2013",資料!$J:$J,"4",資料!$O:$O,"V") -> 0 | K28: =COUNTIFS(資料!$C:$C,D28,資料!$I:$I,"2013",資料!$J:$J,"4") -> 0 | L28: =J28/AVERAGE(E28,F28) -> 0 | M28: =K28/AVERAGE(E28,F28) -> 0 | N28: =(G28+K28)/AVERAGE(E28,F28) -> 0
D29: 友達-資收區(三期) | E29: 8 | F29: 8 | G29: =COUNTIFS(資料!$C:$C,D29,資料!$G:$G,"2013",資料!$H:$H,"4") -> 0 | H29: 0 | I29: 0 | J29: =COUNTIFS(資料!$C:$C,D29,資料!$I:$I,"2013",資料!$J:$J,"4",資料!$O:$O,"V") -> 0 | K29: =COUNTIFS(資料!$C:$C,D29,資料!$I:$I,"2013",資料!$J:$J,"4") -> 0 | L29: =J29/AVERAGE(E29,F29) -> 0 | M29: =K29/AVERAGE(E29,F29) -> 0 | N29: =(G29+K29)/AVERAGE(E29,F29) -> 0
D30: 友達-包材區 | E30: 11 | F30: 11 | G30: =COUNTIFS(資料!$C:$C,D30,資料!$G:$G,"2013",資料!$H:$H,"4") -> 0 | H30: 0 | I30: 0 | J30: =COUNTIFS(資料!$C:$C,D30,資料!$I:$I,"2013",資料!$J:$J,"4",資料!$O:$O,"V") -> 0 | K30: =COUNTIFS(資料!$C:$C,D30,資料!$I:$I,"2013",資料!$J:$J,"4") -> 0 | L30: =J30/AVERAGE(E30,F30) -> 0 | M30: =K30/AVERAGE(E30,F30) -> 0 | N30: =(G30+K30)/AVERAGE(E30,F30) -> 0
D31: 友達-后里包材清潔區 | E31: 29 | F31: 31 | G31: =COUNTIFS(資料!$C:$C,D31,資料!$G:$G,"2013",資料!$H:$H,"4") -> 2 | H31: 0 | I31: 0 | J31: =COUNTIFS(資料!$C:$C,D31,資料!$I:$I,"2013",資料!$J:$J,"4",資料!$O:$O,"V") -> 0 | K31: =COUNTIFS(資料!$C:$C,D31,資料!$I:$I,"2013",資料!$J:$J,"4") -> 0 | L31: =J31/AVERAGE(E31,F31) -> 0 | M31: =K31/AVERAGE(E31,F31) -> 0 | N31: =(G31+K31)/AVERAGE(E31,F31) -> 0.066666667
D32: 友達-后里包材清潔區(人力仲介) | E32: 5 | F32: 3 | G32: =COUNTIFS(資料!$C:$C,D32,資料!$G:$G,"2013",資料!$H:$H,"4") -> 0 | H32: 0 | I32: 0 | J32: =COUNTIFS(資料!$C:$C,D32,資料!$I:$I,"2013",資料!$J:$J,"4",資料!$O:$O,"V") -> 0 | K32: 2 | L32: =J32/AVERAGE(E32,F32) -> 0 | M32: =K32/AVERAGE(E32,F32) -> 0.5 | N32: =(G32+K32)/AVERAGE(E32,F32) -> 0.5
D33: 友達-資收區(七星) | E33: 6 | F33: 6 | G33: =COUNTIFS(資料!$C:$C,D33,資料!$G:$G,"2013",資料!$H:$H,"4") -> 0 | J33: =COUNTIFS(資料!$C:$C,D33,資料!$I:$I,"2013",資料!$J:$J,"4",資料!$O:$O,"V") -> 0 | K33: =COUNTIFS(資料!$C:$C,D33,資料!$I:$I,"2013",資料!$J:$J,"4") -> 0 | L33: =J33/AVERAGE(E33,F33) -> 0 | M33: =K33/AVERAGE(E33,F33) -> 0 | N33: =(G33+K33)/AVERAGE(E33,F33) -> 0
B34: 北區市場開發部 | E34: 1 | F34: 2 | G34: =COUNTIFS(資料!$C:$C,B34,資料!$G:$G,"2013",資料!$H:$H,"4") -> 1 | H34: 0 | I34: 0 | J34: =COUNTIFS(資料!$C:$C,B34,資料!$I:$I,"2013",資料!$J:$J,"4",資料!$O:$O,"V") -> 0 | K34: =COUNTIFS(資料!$C:$C,D34,資料!$I:$I,"2013",資料!$J:$J,"4") -> 0 | L34: =J34/AVERAGE(E34,F34) -> 0 | M34: =K34/AVERAGE(E34,F34) -> 0 | N34: =(G34+K34)/AVERAGE(E34,F34) -> 0.66666667
B35: 北區-倉儲物流管理部 | C35: 北部資收 | D35: 蘆竹 | E35: 5 | F35: 5 | G35: =COUNTIFS(資料!$C:$C,C35,資料!$G:$G,"2013",資料!$H:$H,"4") -> 0 | J35: =COUNTIFS(資料!$C:$C,B34,資料!$I:$I,"2013",資料!$J:$J,"4",資料!$O:$O,"V") -> 0 | K35: =COUNTIFS(資料!$C:$C,C35,資料!$I:$I,"2013",資料!$J:$J,"4") -> 0 | L35: =J35/AVERAGE(E35,F35) -> 0 | M35: =K35/AVERAGE(E35,F35) -> 0 | N35: =(G35+K35)/AVERAGE(E35,F35) -> 0
D36: 龍潭
D37: 桃園
B38: 南區市場開發部 | E38: 4 | F38: 4 | G38: =COUNTIFS(資料!$C:$C,B38,資料!$G:$G,"2013",資料!$H:$H,"4") -> 0 | J38: =COUNTIFS(資料!$C:$C,B38,資料!$I:$I,"2013",資料!$J:$J,"4",資料!$O:$O,"V") -> 0 | K38: =COUNTIFS(資料!$C:$C,B38,資料!$I:$I,"2013",資料!$J:$J,"4") -> 0 | L38: =J38/AVERAGE(E38,F38) -> 0 | M38: =K38/AVERAGE(E38,F38) -> 0 | N38: =(G38+K38)/AVERAGE(E38,F38) -> 0
B39: 南區-倉儲物流管理部 | C39: 南部專案 | D39: 南科3m | E39: 33 | F39: 26 | G39: =COUNTIFS(資料!$C:$C,D39,資料!$G:$G,"2013",資料!$H:$H,"4") -> 0 | J39: =COUNTIFS(資料!$C:$C,D39,資料!$I:$I,"2013",資料!$J:$J,"4",資料!$O:$O,"V") -> 7 | K39: =COUNTIFS(資料!$C:$C,D39,資料!$I:$I,"2013",資料!$J:$J,"4") -> 7 | L39: =J39/AVERAGE(E39,F39) -> 0.23728814 | M39: =K39/AVERAGE(E39,F39) -> 0.23728814 | N39: =(G39+K39)/AVERAGE(E39,F39) -> 0.23728814
D40: 中強 | E40: 1 | F40: 1 | G40: =COUNTIFS(資料!$C:$C,D40,資料!$G:$G,"2013",資料!$H:$H,"4") -> 0 | J40: =COUNTIFS(資料!$C:$C,D40,資料!$I:$I,"2013",資料!$J:$J,"4",資料!$O:$O,"V") -> 0 | K40: =COUNTIFS(資料!$C:$C,D40,資料!$I:$I,"2013",資料!$J:$J,"4") -> 0 | L40: =J40/AVERAGE(E40,F40) -> 0 | M40: =K40/AVERAGE(E40,F40) -> 0 | N40: =(G40+K40)/AVERAGE(E40,F40) -> 0
...

Sheet 到職
B1: 部門 | C1: 工號 | D1: 姓名 | E1: 職位 | F1: 到職日 | G1: 勞健保 | H1: 備註
B2: 網管工程課 | C2: 04303 | D2: 蔡孟儒 | E2: 工程師 | F2: 45663 | G2: 01/06加保
B3: 中區業務一課(金馬站) | C3: 04304 | D3: 邱滿堂 | E3: 作業員 | F3: 45659 | G3: 01/02加保
B4: 中區業務一課(中三) | C4: 04305 | D4: 高博文 | E4: 拖車司機 | F4: 45672 | G4: 01/15加保
B6: 加盟部 | C6: 04306 | D6: 滕芸 | E6: 管理師 | F6: 45691 | G6: 2/3加保 | H6: 加保於青心
B7: 行銷部 | C7: 04307 | D7: 許湘琦 | E7: 副管理師 | F7: 2025/2/3 | G7: 2/3加保
B8: 財務部 | C8: 04310 | D8: 謝旻哲 | E8: 工讀生 | F8: 45691 | G8: 2/3加保
B9: 廢車客服課 | C9: 04308 | D9: 劉思欣 | E9: 助理管理師 | F9: 45693 | G9: 2/5加保
B10: 廢車客服課 | C10: 04309 | D10: 李品慈 | E10: 助理管理師 | F10: 45693 | G10: 2/5加保
B11: 企業客服課 | C11: 04311 | D11: 蘇子堯 | E11: 助理管理師 | F11: 45698 | G11: 2/10加保
B12: 人資課 | C12: 04312 | D12: 陳資蓉 | E12: 副管理師 | F12: 45705 | G12: 2/17加保
B13: 全興造粒課 | C13: 04313 | D13: 王士駿 | E13: 外場人員 | F13: 45705 | G13: 2/17加保
B14: 南區業務一課 | C14: 04314 | D14: 田瑋群 | E14: 夾子車司機 | F14: 45705 | G14: 2/17加保
B15: 全興造粒課 | C15: 04315 | D15: 書帕差 | E15: 移工 | F15: 45712 | G15: 2/24加保
B17: 草屯站 | C17: 04322 | D17: 陳繼華 | E17: 顧問 | F17: 45717 | G17: 3/1加保
B18: 營運部 | C18: 04316 | D18: 林庭鋐 | E18: 管理師 | F18: 45719 | G18: 3/3加保
B19: 北區業務三課 | C19: 04318 | D19: 江柏寰 | E19: 工讀生 | F19: 45719 | G19: 3/3加保
B20: 中區業務一課(沙鹿倉) | C20: 04320 | D20: 王子珉 | E20: 儲備夾子車司機 | F20: 45721 | G20: 3/5加保
... B25: 南區業務一課 | C25: 04324 | D25: 林于翔 | E25: 夾子車司機 | F25: 45728 | G25: 3/12加保
B26: 全興處理一課 | C26: 04325 | D26: 書拉財 | E26: 移工 | F26: 45733 | G26: 3/16加保 | H26: 3/16入境，3/17上班
B27: 員林站 | C27: 04326 | D27: 詹偉賢 | E27: 外場人員 | F27: 45735 | G27: 3/19加保
B28: 北區業務一課 | C28: 04327 | D28: 陳基展 | E28: 作業員(駐博智電子) | F28: 45740 | G28: 3/24加保
B29: 和美站 | C29: 04328 | D29: 張鴻祥 | E29: 拖車司機 | F29: 45740 | G29: 3/24加保
B31: 拆除工程課 | C31: 04330 | D31: 陳俊緯 | E31: 夾子車司機 | F31: 45754 | G31: 4/7加保
B32: 神岡站 | C32: 04331 | D32: 林縉佑 | E32: 儲備拖車司機 | F32: 45754 | G32: 4/7加保
B33: 南區業務一課 | C33: 04332 | D33: 李世昌 | E33: 儲備夾子車司機 | F33: 45754 | G33: 4/7加保
B34: 法務及環安課 | C34: 04329 | D34: 陳俊成 | E34: 管理師 | F34: 45755 | G34: 4/8加保
B35: 北區業務一課 | C35: 04333 | D35: 呂鵬 | E35: 3.5T小車司機 | F35: 45763 | G35: 4/16加保
B36: 金馬站 | C36: 04334 | D36: 鄭錫堯 | E36: 3.5T小車司機 | F36: 45770 | G36: 4/23加保
B37: 北區業務三課 | C37: 04335 | D37: 許正學 | E37: 作業員(晚班) | F37: 45771 | G37: 4/24加保
B39: 北區業務二課 | D39: 葉科旻 | E39: 作業員 | F39: 45782 | G39: 5/5加保 | H39: 加保 3合1、團保
B40: 北區業務二課 | C40: 04336 | D40: 鍾雲青 | E40: 作業員 | F40: 45782 | G40: 5/5加保
B41: 全興處理二課 | C41: 04337 | D41: 薩拉育 | E41: 移工 | F41: 2025/5/5 (5/4入境) | G41: 5/4加保
B42: 神岡站 | C42: 04338 | D42: 陳建勳 | E42: 拖車司機 | F42: 45782 | G42: 5/5加保
B43: 全興處理二課 | C43: 04339 | D43: 納他吳 | E43: 移工 | F43: 45789 | G43: 5/11加保
B44: 中區業務一課 | C44: 04340 | D44: 黃培源 | E44: 作業員(駐矽品中山) | F44: 45796 | G44: 5/19加保
B45: 北區業務二課 | C45: 04341 | D45: 江盛州 | E45: 作業員(駐廠矽品) | F45: 45796 | G45: 5/19加保
B46: 全興造粒課 | C46: 04342 | D46: 班查 | E46: 移工 | F46: 45799 | G46: 5/22加保
B47: 南區業務一課 | C47: 04343 | D47: 方亞庭 | E47: 副管理師(駐美光) | F47: 45803 | G47: 5/26加保
B48: 中區業務一課 | C48: 04344 | D48: 張永興 | E48: 作業員(駐矽品大豐) | F48: 45803 | G48: 5/26加保
...

Sheet checkin4月 
A1: 4月新進
A3: 序 | B3: 薪 | C3: 部門名稱 | D3: 工號 | E3: 姓名 | F3: 職位 | G3: 等 | H3: 穩 | I3: 投 | J3: 勞 | K3: 健 | L3: 職 | M3: 退 | N3: 銀 | O3: 類 | P3: 到職日 | Q3: 加保日 | R3: 備註
A4: 1 | C4: 拆除工程課 | D4: 04330 | E4: 陳俊緯 | F4: 夾子車司機 | P4: 45754 | Q4: 4/7加保
A5: 2 | C5: 神岡站 | D5: 04331 | E5: 林縉佑 | F5: 儲備拖車司機 | P5: 45754 | Q5: 4/7加保
A6: 3 | C6: 南區業務一課 | D6: 04332 | E6: 李世昌 | F6: 儲備夾子車司機 | P6: 45754 | Q6: 4/7加保
A7: 4 | C7: 法務及環安課 | D7: 04329 | E7: 陳俊成 | F7: 管理師 | P7: 45755 | Q7: 4/8加保
A8: 5 | C8: 北區業務三課 | D8: 04008 | E8: 葉衣琪 | F8: 助理會計 | P8: 45758 | Q8: 4/11富保
A9: 6 | C9: 北區業務一課 | D9: 04333 | E9: 呂鵬 | F9: 3.5T小車司機 | P9: 45763 | Q9: 4/16加保
A10: 7 | C10: 金馬站 | D10: 04334 | E10: 鄭錫堯 | F10: 3.5T小車司機 | P10: 45770 | Q10: 4/23加保
A11: 8 | C11: 北區業務三課 | D11: 04335 | E11: 許正學 | F11: 作業員(晚班) | P11: 45771 | Q11: 4/24加保

Sheet checkin1月
A1: 1 | B1: 月新進
A3: 序 | B3: 薪 | H3: 等 | I3: 穩 | J3: 投 | K3: 勞 | L3: 健 | M3: 職 | N3: 退 | O3: 銀 | P3: 類 | T3: B
A4: 1 | C4: 網管工程課 | D4: 04303 | E4: 蔡孟儒 | F4: 工程師 | Q4: 45663 | R4: 01/06加保
A5: 2 | C5: 中區業務一課 | D5: 04304 | E5: 邱滿堂 | F5: 作業員 | Q5: 45659 | R5: 01/02加保
A6: 3 | C6: 中區業務一課(中三) | D6: 04305 | E6: 高博文 | F6: 拖車司機 | Q6: 45672 | R6: 01/15加保
A7: 4
A8: 5
A9: 6
A10: 7
A11: 8
A12: 9
A13: 10
A14: 11
A15: 12
A16: 13
A17: 14
A18: 15
... A23: 20

Sheet 每月離職率
A1: 2013年每月員工人數及每月流動率
A2: 月份 | B2: 月初人數 | C2: 月底人數 | D2: 平均人數 | E2: 新進人數 | F2: 離職人數 | G2: 每月 流動率
A3: 1 | G3: =(F3+E3)/D3 -> #DIV/0!
A4: 2 | G4: =(F4+E4)/D4 -> #DIV/0!
A5: 3 | G5: =(F5+E5)/D5 -> #DIV/0!
A6: 4 | G6: =(F6+E6)/D6 -> #DIV/0!
A7: 5 | G7: =(F7+E7)/D7 -> #DIV/0!
A8: 6 | G8: =(F8+E8)/D8 -> #DIV/0!
A9: 7 | G9: =(F9+E9)/D9 -> #DIV/0!
A10: 8 | G10: =(F10+E10)/D10 -> #DIV/0!
A11: 9 | G11: =(F11+E11)/D11 -> #DIV/0!
A12: 10 | G12: =(F12+E12)/D12 -> #DIV/0!
A13: 11 | G13: =(F13+E13)/D13 -> #DIV/0!
A14: 12 | G14: =(F14+E14)/D14 -> #DIV/0!
G15: =AVERAGE(G3:G14) -> #DIV/0!
A20: 2012年每月員工人數及每月流動率
A21: 月份 | B21: 月初人數 | C21: 月底人數 | D21: 平均人數 | E21: 新進人數 | F21: 離職人數 | G21: 每月 流動率
A22: 1 | G22: =(F22+E22)/D22 -> #DIV/0!
A23: 2 | G23: =(F23+E23)/D23 -> #DIV/0!
A24: 3 | G24: =(F24+E24)/D24 -> #DIV/0!
A25: 4 | G25: =(F25+E25)/D25 -> #DIV/0!
A26: 5 | G26: =(F26+E26)/D26 -> #DIV/0!
A27: 6 | G27: =(F27+E27)/D27 -> #DIV/0!
A28: 7 | G28: =(F28+E28)/D28 -> #DIV/0!
A29: 8 | G29: =(F29+E29)/D29 -> #DIV/0!
A30: 9 | G30: =(F30+E30)/D30 -> #DIV/0!
A31: 10 | G31: =(F31+E31)/D31 -> #DIV/0!
A32: 11 | G32: =(F32+E32)/D32 -> #DIV/0!
A33: 12 | G33: =(F33+E33)/D33 -> #DIV/0!
G34: =AVERAGE(G22:G33) -> #DIV/0!

Sheet checkout1月
A1: 1 | B1: 月離職
A3: 序 | B3: 薪 | G3: 作 | H3: 特 | I3: 小時 | J3: 加
A4: 1 | C4: 南區業務一課 | D4: 03863 | E4: 蔡建傑 | F4: 儲備夾子車司機 | M4: 44748 | N4: 45663 | O4: 育嬰留停2025/01/06-2025/06/30
A5: 2 | C5: 中區業務三課 | D5: 03348 | E5: 卓巧宜 | F5: 副管理師 | M5: 43423 | N5: 45663 | O5: 育嬰留停2025/01/06-2025/07/31
A6: 3 | C6: 宏偉處理課 | D6: H0027 | E6: 胡國慶 | F6: 外場人員 | M6: 45635 | N6: 45659
A7: 4 | C7: 中區業務一課 | D7: 02603 | E7: 李武憲 | F7: 作業員 | M7: 42002 | N7: 45679
A8: 5 | C8: 南區業務一課 | D8: 03526 | E8: 張玲翔 | F8: 作業員 | M8: 43808 | N8: 45688
A9: 6 | C9: 全興造粒課 | D9: 04297 | E9: 黃鴻文 | F9: 外場人員 | M9: 45614 | N9: 45688 | O9: 資遣
A10: 7
A11: 8
A12: 9
A13: 10
A14: 11
A15: 12
A16: 13
A17: 14
A18: 15
A19: 16
A20: 17
A21: 18
... A26: 23

Sheet checkin2月
A1: 2 | B1: 月新進
A3: 序 | B3: 薪 | H3: 等 | I3: 穩 | J3: 投 | K3: 勞 | L3: 健 | M3: 職 | N3: 退 | O3: 銀 | P3: 類 | T3: B
A4: 1 | C4: 加盟部 | D4: 04306 | E4: 滕芸 | F4: 管理師 | Q4: 45691 | R4: 2/3加保 | S4: 加保於青心
A5: 2 | C5: 行銷部 | D5: 04307 | E5: 許湘琦 | F5: 副管理師 | Q5: 2025/2/3 | R5: 2/3加保
A6: 3 | C6: 財務部 | D6: 04310 | E6: 謝旻哲 | F6: 工讀生 | Q6: 45691 | R6: 2/3加保
A7: 4 | C7: 廢車客服課 | D7: 04308 | E7: 劉思欣 | F7: 助理管理師 | Q7: 45693 | R7: 2/5加保
A8: 5 | C8: 廢車客服課 | D8: 04309 | E8: 李品慈 | F8: 助理管理師 | Q8: 45693 | R8: 2/5加保
A9: 6 | C9: 企業客服課 | D9: 04311 | E9: 蘇子堯 | F9: 助理管理師 | Q9: 45698 | R9: 2/10加保
A10: 7 | C10: 人資課 | D10: 04312 | E10: 陳資蓉 | F10: 副管理師 | Q10: 45705 | R10: 2/17加保
A11: 8 | C11: 全興造粒課 | D11: 04313 | E11: 王士駿 | F11: 外場人員 | Q11: 45705 | R11: 2/17加保
A12: 9 | C12: 南區業務一課 | D12: 04314 | E12: 田瑋群 | F12: 夾子車司機 | Q12: 45705 | R12: 2/17加保
A13: 10 | C13: 全興造粒課 | D13: 04315 | E13: 書帕差 | F13: 移工 | Q13: 45712 | R13: 2/24加保
A14: 11
A15: 12
A16: 13
A17: 14
A18: 15
A19: 16
A20: 17
A21: 18
A22: 19
A23: 20

Sheet checkout 2月
A1: 2 | B1: 月離職
A3: 序 | B3: 薪 | G3: 作 | H3: 特 | I3: 小時 | J3: 加
A4: 1 | C4: 人資課 | D4: 04238 | E4: 劉以汝 | F4: 副管理師 | M4: 45474 | N4: 45691
A5: 2 | C5: 廢車客服課 | D5: 03377 | E5: 廖芷嵐 | F5: 助理管理師 | M5: 43480 | N5: 45693
A6: 3 | C6: 和美站 | D6: 02335 | E6: 蔡政德 | F6: 拖車司機 | M6: 41463 | N6: 45701
A7: 4 | C7: 中區業務一課 | D7: 04276 | E7: 劉羽程 | F7: 作業員 | M7: 45551 | N7: 45705
A8: 5 | C8: 管理課 | D8: 04182 | E8: 林佳瑩 | F8: 助理管理師 | M8: 45355 | N8: 45709
A9: 6 | C9: 北區業務三課 | D9: 03911 | E9: 黃暄育 | F9: 助理會計 | M9: 44858 | N9: 45688
A10: 7 | C10: 業務部行政管理課 | D10: 03017 | E10: 林玉婷 | F10: 專員 | M10: 42870 | N10: 45713
A11: 8 | C11: 北區業務二課 | D11: 03593 | E11: 鍾雲青 | F11: 班長 | M11: 44048 | N11: 45716
A12: 9 | C12: 北區業務二課 | D12: 03464 | E12: 蔡孟蓉 | F12: 分選員 | M12: 43682 | N12: 45716
A13: 10 | C13: 北區業務二課 | D13: 03591 | E13: 楊逸棋 | F13: 作業員 | M13: 44046 | N13: 45716
A14: 11 | C14: 財務部 | D14: 04310 | E14: 謝旻哲 | F14: 工讀生 | M14: 45691 | N14: 45716
A15: 12 | C15: 全興造粒課 | D15: 03915 | E15: 楊宗達 | F15: 班長 | M15: 44866 | N15: 45716
A16: 14
A17: 15
A18: 16
A19: 17
A20: 18
A21: 19
A22: 20
A23: 21
A24: 22
A25: 23

Sheet checkout 4月
A1: 4月離職
A3: 序 | B3: 薪 | C3: 部門名稱 | D3: 工號 | E3: 姓名 | F3: 職位 | G3: 作 | H3: 特 | I3: 小時 | J3: 加 | K3: 到職日 | L3: 離職日 | M3: 備註
A4: 1 | C4: 中區業務一課 | D4: 04305 | E4: 高博文 | F4: 拖車司機 | K4: 45672 | L4: 45751 | M4: 資遣
A5: 2 | C5: 全興處理二課 | D5: 03822 | E5: 阿恩 | F5: 移工 | K5: 44667 | L5: 45755 | M5: 4/8最後工作日，4/10離境退保(結算)
A6: 3 | C6: 和美站 | D6: 04328 | E6: 張鴻祥 | F6: 拖車司機 | K6: 45740 | L6: 45760 | M6: 退保日4/15
A7: 4 | C7: 法務及環安課 | D7: 04329 | E7: 陳俊成 | F7: 管理師 | K7: 45755 | L7: 45761
A8: 5 | C8: 家電客服課 | D8: 04015 | E8: 林金燕 | F8: 助理管理師 | K8: 44991 | L8: 45765
A9: 6 | C9: 法務及環安課 | D9: 03810 | E9: 蔡雅雯 | F9: 管理師 | K9: 44634 | L9: 45765 | M9: 4/19~10/18育嬰留停(4月薪資需補發2月因請假扣款的費用)
A10: 7 | C10: 青心-加盟課 | D10: 04306 | E10: 滕芸 | F10: 管理師 | K10: 45691 | L10: 45769 | M10: 資遣 5/2退保(薪資算到4/22)
A11: 8 | C11: 神岡站 | D11: 04331 | E11: 林縉佑 | F11: 儲備拖車司機 | K11: 45754 | L11: 45772
A12: 9 | C12: 員林站 | D12: 02683 | E12: 朱振隆 | F12: 外場人員 | K12: 42177 | L12: 45777
A13: 10 | C13: 全興造粒課 | D13: 02533 | E13: 彼查 | F13: 移工 | K13: 41834 | L13: 45777 | M13: 4/30最後工作日，5/3離境退保(結算)
A14: 11 | C14: 北區業務三課 | D14: 04258 | E14: 吳慧萍 | F14: 工讀生 | K14: 45516 | L14: 45777
A15: 12 | C15: 中區業務一課 | D15: 04266 | E15: 許新育 | F15: 3.5噸司機 | K15: 45530 | L15: 45777
A16: 13 | C16: 全興處理二課 | D16: 04137 | E16: 帕他拉功 | F16: 移工 | K16: 45187 | L16: 45777 | M16: 4/30最後工作日，5/6離境退保(結算)
A17: 14 | C17: 北區業務三課 | D17: 03961 | E17: 顏士婷 | F17: 班長 | K17: 44917 | L17: 45777

Sheet 離職
A1: EIP表單編碼 | B1: 月份 | C1: 部門 | D1: 工號 | E1: 姓名 | F1: 職稱 | G1: 到職日期 | H1: 離職日 | I1: 退保 | J1: 申請日期 | K1: 年 | L1: 月 | M1: 日 | N1: 天數 | O1: 服務年資 | P1: 細分類 | Q1: 詳細原因 | R1: 歸檔確認 | S1: 離職單 | T1: 離職證明 | U1: 薪資單 | V1: mail發出
A2: 114080001 | B2: 08月 | C2: 行銷部 | D2: 03321 | E2: 陳姿穎 | F2: 管理師 | G2: 43376 | H2: 45879 | I2: 8/10退保 | J2: 45821 | K2: =DATEDIF(G2,H2,"y") -> 6 | L2: =DATEDIF(G2,H2,"ym") -> 10 | M2: =DATEDIF(G2,H2,"MD") -> 7 | N2: =DATEDIF(G2,H2,"d") -> 2503 | O2: =IF(N2<=92,"3個月以下",IF(N2<=365,"3個月至1年",IF(N2<=1095,"1年至3年",IF(N2>1096,"3年以上")))) -> 3年以上 | P2: 個人問題 | R2: □已完成歸檔 □___月生效 □其他： | S2: OK | T2: 需要 | U2: 需要 | V2: 台中市西屯區市政北三路113號10樓之5
A3: 招募 | B3: 08月 | C3: 人資課 | D3: 04312 | E3: 陳資蓉 | F3: 副管理師 | G3: 45705 | H3: 45877 | I3: 8/8退保 | J3: 45846 | K3: =DATEDIF(G3,H3,"y") -> 0 | L3: =DATEDIF(G3,H3,"ym") -> 5 | M3: =DATEDIF(G3,H3,"MD") -> 22 | N3: =DATEDIF(G3,H3,"d") -> 172 | O3: =IF(N3<=92,"3個月以下",IF(N3<=365,"3個月至1年",IF(N3<=1095,"1年至3年",IF(N3>1096,"3年以上")))) -> 3個月至1年 | P3: 個人問題 | R3: □已完成歸檔 □___月生效 □其他： | S3: OK | T3: 需要，8/12寄 | U3: NO | V3: 台中市新社區協成里華豐三街60號
A4: 114080003 | B4: 08月 | C4: 草屯站 | D4: 00033 | E4: 李志仁 | F4: 主任 | G4: 37712 | H4: 45900 | I4: 9/1退保 | J4: 45870 | K4: =DATEDIF(G4,H4,"y") -> 22 | L4: =DATEDIF(G4,H4,"ym") -> 4 | M4: =DATEDIF(G4,H4,"MD") -> 30 | N4: =DATEDIF(G4,H4,"d") -> 8188 | O4: =IF(N4<=92,"3個月以下",IF(N4<=365,"3個月至1年",IF(N4<=1095,"1年至3年",IF(N4>1096,"3年以上")))) -> 3年以上 | P4: 資遣 | R4: □已完成歸檔 □___月生效 □其他： | S4: X | T4: 非自願OK
A5: 114080004 | B5: 08月 | C5: 五股分選課 | D5: 03538 | E5: 呂軍億 | F5: 組長 | G5: 43864 | H5: 45900 | I5: 9/1退保 | J5: 45874 | K5: =DATEDIF(G5,H5,"y") -> 5 | L5: =DATEDIF(G5,H5,"ym") -> 6 | M5: =DATEDIF(G5,H5,"MD") -> 28 | N5: =DATEDIF(G5,H5,"d") -> 2036 | O5: =IF(N5<=92,"3個月以下",IF(N5<=365,"3個月至1年",IF(N5<=1095,"1年至3年",IF(N5>1096,"3年以上")))) -> 3年以上 | P5: 個人問題 | R5: □已完成歸檔 □___月生效 □其他： | S5: OK | T5: 需要 | U5: 需要 | V5: 新北市八里區龍米路二段228-22號2樓
A6: 114080005 | B6: 08月 | C6: 中區業務一課 | D6: 04379 | E6: 傅文吉 | F6: 作業員 | G6: 45873 | H6: 45874 | I6: 8/6退保 | J6: 45875 | K6: =DATEDIF(G6,H6,"y") -> 0 | L6: =DATEDIF(G6,H6,"ym") -> 0 | M6: =DATEDIF(G6,H6,"MD") -> 1 | N6: =DATEDIF(G6,H6,"d") -> 1 | O6: =IF(N6<=92,"3個月以下",IF(N6<=365,"3個月至1年",IF(N6<=1095,"1年至3年",IF(N6>1096,"3年以上")))) -> 3個月以下 | P6: 個人問題 | R6: □已完成歸檔 □___月生效 □其他： | S6: OK | T6: NO | U6: NO
A7: 114080006 | B7: 08月 | C7: 中區業務一課 | D7: 04360 | E7: 楊琪伊 | F7: 物流專員 | G7: 45854 | H7: 45877 | I7: 8/8退保 | J7: 45877 | K7: =DATEDIF(G7,H7,"y") -> 0 | L7: =DATEDIF(G7,H7,"ym") -> 0 | M7: =DATEDIF(G7,H7,"MD") -> 23 | N7: =DATEDIF(G7,H7,"d") -> 23 | O7: =IF(N7<=92,"3個月以下",IF(N7<=365,"3個月至1年",IF(N7<=1095,"1年至3年",IF(N7>1096,"3年以上")))) -> 3個月以下 | P7: 個人問題 | Q7: 太長加班 | R7: □已完成歸檔 □___月生效 □其他： | S7: OK | T7: 需要 | U7: 需要 | V7: 台中市清水區港都路163號5樓之6
A8: 114080007 | B8: 08月 | C8: 軟體開發課 | D8: 04287 | E8: 陳鈺燻 | F8: 副工程師 | G8: 45586 | H8: 45879 | I8: 8/10退保 | J8: 45880 | K8: =DATEDIF(G8,H8,"y") -> 0 | L8: =DATEDIF(G8,H8,"ym") -> 9 | M8: =DATEDIF(G8,H8,"MD") -> 20 | N8: =DATEDIF(G8,H8,"d") -> 293 | O8: =IF(N8<=92,"3個月以下",IF(N8<=365,"3個月至1年",IF(N8<=1095,"1年至3年",IF(N8>1096,"3年以上")))) -> 3個月至1年 | P8: 資遣 | R8: □已完成歸檔 □___月生效 □其他： | S8: OK | T8: 非自願OK
A9: 114080008 | B9: 08月 | C9: 網管工程課 | D9: 03490 | E9: 石培瀚 | F9: 副工程師 | G9: 43724 | H9: 45878 | I9: 8/9退保 | J9: 45880 | K9: =DATEDIF(G9,H9,"y") -> 5 | L9: =DATEDIF(G9,H9,"ym") -> 10 | M9: =DATEDIF(G9,H9,"MD") -> 24 | N9: =DATEDIF(G9,H9,"d") -> 2154 | O9: =IF(N9<=92,"3個月以下",IF(N9<=365,"3個月至1年",IF(N9<=1095,"1年至3年",IF(N9>1096,"3年以上")))) -> 3年以上 | P9: 資遣 | R9: □已完成歸檔 □___月生效 □其他： | S9: OK | T9: 非自願OK
A10: 114080009 | B10: 08月 | C10: 五股分選課 | D10: 04387 | E10: 黃詔熙 | F10: 作業員 | G10: 45880 | H10: 45880 | I10: 8/11退保 | J10: 45880 | K10: =DATEDIF(G10,H10,"y") -> 0 | L10: =DATEDIF(G10,H10,"ym") -> 0 | M10: =DATEDIF(G10,H10,"MD") -> 0 | N10: =DATEDIF(G10,H10,"d") -> 0 | O10: =IF(N10<=92,"3個月以下",IF(N10<=365,"3個月至1年",IF(N10<=1095,"1年至3年",IF(N10>1096,"3年以上")))) -> 3個月以下 | P10: 個人問題 | R10: □已完成歸檔 □___月生效 □其他： | S10: OK | T10: NO | U10: NO
A11: 114080010 | B11: 08月 | C11: 中區業務一課 | D11: 04378 | E11: 林廣銘 | F11: 作業員 | G11: 45873 | H11: 45884 | I11: 8/15退保 | J11: 45881 | K11: =DATEDIF(G11,H11,"y") -> 0 | L11: =DATEDIF(G11,H11,"ym") -> 0 | M11: =DATEDIF(G11,H11,"MD") -> 11 | N11: =DATEDIF(G11,H11,"d") -> 11 | O11: =IF(N11<=92,"3個月以下",IF(N11<=365,"3個月至1年",IF(N11<=1095,"1年至3年",IF(N11>1096,"3年以上")))) -> 3個月以下 | P11: 個人問題 | R11: □已完成歸檔 □___月生效 □其他： | S11: OK | T11: NO | U11: NO
A12: 114080011 | B12: 08月 | C12: 業務課 | D12: 03335 | E12: 徐筠棋 | F12: 高級業務專員 | G12: 43405 | H12: 45892 | I12: 8/23退保 | J12: 45882 | K12: =DATEDIF(G12,H12,"y") -> 6 | L12: =DATEDIF(G12,H12,"ym") -> 9 | M12: =DATEDIF(G12,H12,"MD") -> 22 | N12: =DATEDIF(G12,H12,"d") -> 2487 | O12: =IF(N12<=92,"3個月以下",IF(N12<=365,"3個月至1年",IF(N12<=1095,"1年至3年",IF(N12>1096,"3年以上")))) -> 3年以上 | P12: 資遣 | R12: □已完成歸檔 □___月生效 □其他： | S12: X
A13: 114080012 | B13: 08月 | C13: 南區業務二課 | D13: 04381 | E13: 李全再 | F13: 夾子車司機 | G13: 45873 | H13: 45884 | I13: 8/15退保 | J13: 45884 | K13: =DATEDIF(G13,H13,"y") -> 0 | L13: =DATEDIF(G13,H13,"ym") -> 0 | M13: =DATEDIF(G13,H13,"MD") -> 11 | N13: =DATEDIF(G13,H13,"d") -> 11 | O13: =IF(N13<=92,"3個月以下",IF(N13<=365,"3個月至1年",IF(N13<=1095,"1年至3年",IF(N13>1096,"3年以上")))) -> 3個月以下 | P13: 身體因素 | R13: □已完成歸檔 □___月生效 □其他： | S13: OK | T13: 需要 | U13: 需要 | V13: 高雄市小港區孔宅里孔宅街4號
A14: 114080013 | B14: 08月 | C14: 中區業務一課 | D14: 04380 | E14: 林品如 | F14: 作業員 | G14: 45873 | H14: 45884 | I14: 8/15退保 | J14: 45884 | K14: =DATEDIF(G14,H14,"y") -> 0 | L14: =DATEDIF(G14,H14,"ym") -> 0 | M14: =DATEDIF(G14,H14,"MD") -> 11 | N14: =DATEDIF(G14,H14,"d") -> 11 | O14: =IF(N14<=92,"3個月以下",IF(N14<=365,"3個月至1年",IF(N14<=1095,"1年至3年",IF(N14>1096,"3年以上")))) -> 3個月以下 | P14: 個人問題 | R14: □已完成歸檔 □___月生效 □其他： | S14: OK | T14: NO | U14: 需要 連同體檢報告一起寄回 | V14: 台中市清水區橋頭里民有路260巷2號
A15: 114080014 | B15: 08月 | C15: 中區業務一課 | D15: 04346 | E15: 何政風 | F15: 拖車司機 | G15: 45803 | H15: 45897 | I15: 8/28退保 | J15: 45888 | K15: =DATEDIF(G15,H15,"y") -> 0 | L15: =DATEDIF(G15,H15,"ym") -> 3 | M15: =DATEDIF(G15,H15,"MD") -> 2 | N15: =DATEDIF(G15,H15,"d") -> 94 | O15: =IF(N15<=92,"3個月以下",IF(N15<=365,"3個月至1年",IF(N15<=1095,"1年至3年",IF(N15>1096,"3年以上")))) -> 3個月至1年 | P15: 資遣 | R15: □已完成歸檔 □___月生效 □其他： | S15: X
A16: 114080015 | B16: 08月 | C16: 中區業務一課 | D16: 04355 | E16: 彭志翔 | F16: 作業員 | G16: 45826 | H16: 45898 | I16: 8/29退保 | J16: 45889 | K16: =DATEDIF(G16,H16,"y") -> 0 | L16: =DATEDIF(G16,H16,"ym") -> 2 | M16: =DATEDIF(G16,H16,"MD") -> 11 | N16: =DATEDIF(G16,H16,"d") -> 72 | O16: =IF(N16<=92,"3個月以下",IF(N16<=365,"3個月至1年",IF(N16<=1095,"1年至3年",IF(N16>1096,"3年以上")))) -> 3個月以下 | P16: 資遣 | R16: □已完成歸檔 □___月生效 □其他： | S16: X
A17: 114080016 | B17: 08月 | C17: 南區業務一課 | D17: 04070 | E17: 陳賢鈺 | F17: 夾子車司機 | G17: 45054 | H17: 45891 | I17: 8/22退保 | J17: 45889 | K17: =DATEDIF(G17,H17,"y") -> 2 | L17: =DATEDIF(G17,H17,"ym") -> 3 | M17: =DATEDIF(G17,H17,"MD") -> 14 | N17: =DATEDIF(G17,H17,"d") -> 837 | O17: =IF(N17<=92,"3個月以下",IF(N17<=365,"3個月至1年",IF(N17<=1095,"1年至3年",IF(N17>1096,"3年以上")))) -> 1年至3年 | P17: 身體因素 | R17: □已完成歸檔 □___月生效 □其他： | S17: OK | T17: 需要 | U17: 需要 | V17: 台南市安定區港口里港口241-12號
A18: 114080017 | B18: 08月 | C18: 南區業務一課 | D18: 04389 | E18: 黃瑞堂 | F18: 作業員 | G18: 45889 | H18: 45890 | I18: 8/21退保 | J18: 45890 | K18: =DATEDIF(G18,H18,"y") -> 0 | L18: =DATEDIF(G18,H18,"ym") -> 0 | M18: =DATEDIF(G18,H18,"MD") -> 1 | N18: =DATEDIF(G18,H18,"d") -> 1 | O18: =IF(N18<=92,"3個月以下",IF(N18<=365,"3個月至1年",IF(N18<=1095,"1年至3年",IF(N18>1096,"3年以上")))) -> 3個月以下 | P18: 個人問題 | R18: □已完成歸檔 □___月生效 □其他： | S18: OK | T18: NO | U18: NO
A19: 114080018 | B19: 08月 | C19: 員林站 | D19: 04349 | E19: 鄭志勝 | F19: 外場人員 | G19: 45810 | H19: 45896 | I19: 8/27退保 | J19: 45891 | K19: =DATEDIF(G19,H19,"y") -> 0 | L19: =DATEDIF(G19,H19,"ym") -> 2 | M19: =DATEDIF(G19,H19,"MD") -> 25 | N19: =DATEDIF(G19,H19,"d") -> 86 | O19: =IF(N19<=92,"3個月以下",IF(N19<=365,"3個月至1年",IF(N19<=1095,"1年至3年",IF(N19>1096,"3年以上")))) -> 3個月以下 | P19: 個人問題 | Q19: 原訂8/31離職,因身體因素調整離職日為8/27 | R19: □已完成歸檔 □___月生效 □其他： | S19: OK | T19: 需要 | U19: 需要 | V19: 彰化縣二水鄉合興村英義路32號
A20: 114080019 | B20: 08月 | C20: 北區業務二課 | D20: 03555 | E20: 劉春保 | F20: 作業員 | G20: 43906 | H20: 45900 | J20: 45895 | K20: =DATEDIF(G20,H20,"y") -> 5 | L20: =DATEDIF(G20,H20,"ym") -> 5 | M20: =DATEDIF(G20,H20,"MD") -> 15 | N20: =DATEDIF(G20,H20,"d") -> 1994 | O20: =IF(N20<=92,"3個月以下",IF(N20<=365,"3個月至1年",IF(N20<=1095,"1年至3年",IF(N20>1096,"3年以上")))) -> 3年以上 | P20: 家庭因素 | R20: □已完成歸檔 □___月生效 □其他： | S20: OK | T20: NO | U20: 需要 | V20: 新竹縣竹北市福德里18鄰三民路494巷1號
A21: 114080020 | B21: 08月 | C21: 再生紡織設計部 | D21: 04259 | E21: 趙建豪 | F21: 高級工程師 | G21: 45516 | H21: 45900 | I21: 9/1退保 | J21: 45897 | K21: =DATEDIF(G21,H21,"y") -> 1 | L21: =DATEDIF(G21,H21,"ym") -> 0 | M21: =DATEDIF(G21,H21,"MD") -> 19 | N21: =DATEDIF(G21,H21,"d") -> 384 | O21: =IF(N21<=92,"3個月以下",IF(N21<=365,"3個月至1年",IF(N21<=1095,"1年至3年",IF(N21>1096,"3年以上")))) -> 1年至3年 | P21: 資遣 | R21: □已完成歸檔 □___月生效 □其他： | S21: X | T21: 需要 | U21: 需要 | V21: 台中市北區漢口路三段78號4F之7
A22: 114080021 | B22: 08月 | C22: 企業客服課 | D22: 04377 | E22: 陳威錡 | F22: 工讀生 | G22: 45873 | H22: 45900 | I22: 9/1退保 | J22: 45898 | K22: =DATEDIF(G22,H22,"y") -> 0 | L22: =DATEDIF(G22,H22,"ym") -> 0 | M22: =DATEDIF(G22,H22,"MD") -> 27 | N22: =DATEDIF(G22,H22,"d") -> 27 | O22: =IF(N22<=92,"3個月以下",IF(N22<=365,"3個月至1年",IF(N22<=1095,"1年至3年",IF(N22>1096,"3年以上")))) -> 3個月以下 | P22: 個人問題 | Q22: 學校開學 | R22: □已完成歸檔 □___月生效 □其他： | T22: NO | U22: NO
A23: 114080022 | B23: 08月 | C23: 企業客服課 | D23: 04362 | E23: 車延信 | F23: 工讀生 | G23: 45847 | H23: 45900 | I23: 9/1退保 | J23: 45898 | K23: =DATEDIF(G23,H23,"y") -> 0 | L23: =DATEDIF(G23,H23,"ym") -> 1 | M23: =DATEDIF(G23,H23,"MD") -> 22 | N23: =DATEDIF(G23,H23,"d") -> 53 | O23: =IF(N23<=92,"3個月以下",IF(N23<=365,"3個月至1年",IF(N23<=1095,"1年至3年",IF(N23>1096,"3年以上")))) -> 3個月以下 | P23: 個人問題 | Q23: 學校開學 | R23: □已完成歸檔 □___月生效 □其他： | T23: NO | U23: NO
A24: 114080023 | B24: 08月 | C24: 中區業務一課 | D24: 03700 | E24: 吳思維 | F24: 拖車司機 | G24: 44396 | H24: 45900 | J24: 45903 | K24: =DATEDIF(G24,H24,"y") -> 4 | L24: =DATEDIF(G24,H24,"ym") -> 1 | M24: =DATEDIF(G24,H24,"MD") -> 12 | N24: =DATEDIF(G24,H24,"d") -> 1504 | O24: =IF(N24<=92,"3個月以下",IF(N24<=365,"3個月至1年",IF(N24<=1095,"1年至3年",IF(N24>1096,"3年以上")))) -> 3年以上 | P24: 育嬰留停 | Q24: 留停期間9/1~9/30 | R24: □已完成歸檔 □___月生效 □其他：
A26: 114090001 | B26: 09月 | C26: 五股分選課 | D26: 04008 | E26: 葉衣琪 | F26: 助理會計 | G26: 44977 | H26: 45915 | I26: 9/15退保 | J26: 45884 | K26: =DATEDIF(G26,H26,"y") -> 2 | L26: =DATEDIF(G26,H26,"ym") -> 6 | M26: =DATEDIF(G26,H26,"MD") -> 26 | N26: =DATEDIF(G26,H26,"d") -> 938 | O26: =IF(N26<=92,"3個月以下",IF(N26<=365,"3個月至1年",IF(N26<=1095,"1年至3年",IF(N26>1096,"3年以上")))) -> 1年至3年 | P26: 家庭因素 | Q26: 原訂9/30離職,個人因素調整為9/15 | R26: □已完成歸檔 □___月生效 □其他： | S26: V | T26: V | U26: V | V26: 新北市蘆洲區中正路174巷36號4樓
A27: 114090002 | B27: 09月 | C27: 企業客服課 | D27: 04361 | E27: 謝榮家 | F27: 工讀生 | G27: 45847 | H27: 45905 | I27: 9/5退保 | J27: 45897 | K27: =DATEDIF(G27,H27,"y") -> 0 | L27: =DATEDIF(G27,H27,"ym") -> 1 | M27: =DATEDIF(G27,H27,"MD") -> 27 | N27: =DATEDIF(G27,H27,"d") -> 58 | O27: =IF(N27<=92,"3個月以下",IF(N27<=365,"3個月至1年",IF(N27<=1095,"1年至3年",IF(N27>1096,"3年以上")))) -> 3個月以下 | P27: 個人問題 | Q27: 學校開學 | R27: □已完成歸檔 □___月生效 □其他： | T27: X | U27: X
A28: 114090003 | B28: 09月 | C28: 企業客服課 | D28: 04363 | E28: 王君泰 | F28: 工讀生 | G28: 45847 | H28: 45902 | I28: 9/2退保 | J28: 45897 | K28: =DATEDIF(G28,H28,"y") -> 0 | L28: =DATEDIF(G28,H28,"ym") -> 1 | M28: =DATEDIF(G28,H28,"MD") -> 24 | N28: =DATEDIF(G28,H28,"d") -> 55 | O28: =IF(N28<=92,"3個月以下",IF(N28<=365,"3個月至1年",IF(N28<=1095,"1年至3年",IF(N28>1096,"3年以上")))) -> 3個月以下 | P28: 個人問題 | Q28: 學校開學 | R28: □已完成歸檔 □___月生效 □其他： | T28: X | U28: X
A29: 114090004 | B29: 09月 | C29: 行銷部 | D29: 04357 | E29: 黃詩庭 | F29: 工讀生 | G29: 45839 | H29: 45912 | I29: 9/12退保 | J29: 45897 | K29: =DATEDIF(G29,H29,"y") -> 0 | L29: =DATEDIF(G29,H29,"ym") -> 2 | M29: =DATEDIF(G29,H29,"MD") -> 11 | N29: =DATEDIF(G29,H29,"d") -> 73 | O29: =IF(N29<=92,"3個月以下",IF(N29<=365,"3個月至1年",IF(N29<=1095,"1年至3年",IF(N29>1096,"3年以上")))) -> 3個月以下 | P29: 個人問題 | Q29: 合約到期 | R29: □已完成歸檔 □___月生效 □其他： | S29: V | T29: V | U29: V | V29: 台中市清水區中社裡22鄰建國路122號14樓之一
A30: 114090005 | B30: 09月 | C30: 拆除工程課 | D30: 04330 | E30: 陳俊緯 | F30: 夾子車司機 | G30: 45754 | H30: 45912 | I30: 9/12退保 | J30: 45902 | K30: =DATEDIF(G30,H30,"y") -> 0 | L30: =DATEDIF(G30,H30,"ym") -> 5 | M30: =DATEDIF(G30,H30,"MD") -> 5 | N30: =DATEDIF(G30,H30,"d") -> 158 | O30: =IF(N30<=92,"3個月以下",IF(N30<=365,"3個月至1年",IF(N30<=1095,"1年至3年",IF(N30>1096,"3年以上")))) -> 3個月至1年 | P30: 個人問題 | R30: □已完成歸檔 □___月生效 □其他： | S30: V | T30: X | U30: V | V30: 台中市東勢區文新街278巷17號3樓
A31: 114090006 | B31: 09月 | C31: 全興造粒課 | D31: 03928 | E31: 李暘陞 | F31: 作業員 | G31: 44879 | H31: 45912 | I31: 9/12退保 | J31: 45903 | K31: =DATEDIF(G31,H31,"y") -> 2 | L31: =DATEDIF(G31,H31,"ym") -> 9 | M31: =DATEDIF(G31,H31,"MD") -> 29 | N31: =DATEDIF(G31,H31,"d") -> 1033 | O31: =IF(N31<=92,"3個月以下",IF(N31<=365,"3個月至1年",IF(N31<=1095,"1年至3年",IF(N31>1096,"3年以上")))) -> 1年至3年 | P31: 個人問題 | R31: □已完成歸檔 □___月生效 □其他： | S31: V | T31: X | U31: X
